Workbook

Sheet SF2_Default
G1: School Form 2 (SF 2) Default List
E4: School ID | G4: 406295 | I4: Region | J4: NCR | M4: Division | T4: District
D6: School Name | G6: MANILA CATHEDRAL SCHOOL | N6: School Year | Q6: 2026-2027 | T6: Grade Level | V6: Grade 8 | X6: Section | Y6: St. Faustina Kowalska
F7: Input Data --> | G7: 18bv1eDZ44WeRUvI57WYYa2WssBKnPdYiw2kY3-7jC3Q | H7: Last Male row --> | I7: =IFERROR(__xludf.DUMMYFUNCTION("importrange(CONCATENATE(""https://docs.google.com/spreadsheets/d/"",$F$7),""INPUT DATA!AF11"")"),"#REF!") -> #REF! | J7: =IFERROR(__xludf.DUMMYFUNCTION("importrange(CONCATENATE(""https://docs.google.com/spreadsheets/d/"",$F$7),""INPUT DATA!AF12"")"),"#REF!") -> #REF! | K7: <-- Last Female row
D9: (Last Name, First Name, Middle Name) NAME | H9: * Enrolment as of (1st Friday of June) | N9: Class Adviser | O9: Mr. John Rey Tubello
B10: LRN | C10: ID NUMBER | D10: LEARNER'S NAME | H10: Male | J10: Female
A11: MALE | H11: =H61 -> 21 | J11: =H112 -> 22 | N11: School Principal | O11: Mrs. Lucile Ariette A. Bautista
A12: 1 | B12: 136446180211 | C12: 23-003330 | D12: BONIFACIO LORD RANI KARL PAINAGA | H12: ↑ | J12: ↑
A13: 2 | B13: 136440170036 | C13: 25-001275 | D13: BUCACAO JOHNREEVE KHARI ALFONSO | H13: modify these values when necessary
A14: 3 | B14: 408125180026 | C14: 19-00091 | D14: CANDELARIA JAYREN D
A15: 4 | B15: 406295180045 | C15: 18-00355 | D15: CAY ROJER JYUAN P
A16: 5 | B16: 136432180240 | C16: 25-000460 | D16: CEZAR JOHN MANUEL DE LEON
A17: 6 | B17: 418708180015 | C17: 20-00075 | D17: CONJE LEOBERT JOROS D
A18: 7 | B18: 407900180024 | C18: 25-001588 | D18: DE LEON MARCUS BRENT TITCO
A19: 8 | B19: 408047180004 | C19: 19-00239 | D19: DEL ROSARIO ROBIN DALE A
A20: 9 | B20: 406295180047 | C20: 18-00100 | D20: DIEGO DAN LEONARD Q
A21: 10 | B21: 407956170024 | C21: 19-00097 | D21: GAMBOA OLIVER FRANCOIS Z
A22: 11 | B22: 136435180348 | C22: 25-000134 | D22: GO KELLIN CHASE SAN PEDRO
A23: 12 | B23: 136439180131 | C23: 25-000839 | D23: MALINIS ANDREI JAMES PARAGATOS
A24: 13 | B24: 406295180115 | C24: 18-003875 | D24: PALMA BLAINE XANDER PIMENTEL
A25: 14 | B25: 136435180262 | C25: 25-001190 | D25: POBLETE ARGI CALEB VALENCIA
... A28: 17 | B28: 408227180174 | C28: 25-000718 | D28: ROBLEDO JOHN MIGUEL SERRANO
A29: 18 | B29: \'406295180052 | C29: 18-003660 | D29: SACLOLO JUANCHO JAKOB MAGTOTO
A30: 19 | B30: 136435180301 | C30: 25-001855 | D30: SALANGSANG DION CARLO DIONISIO
A31: 20 | B31: 115281180009 | C31: 25-001426 | D31: SALIGUMBA MAEL CHARLES
A32: 21 | B32: 406295180031 | C32: 2017-61225 | D32: TOLENTINO MARCUS CARSTEN B
A33: 22
A34: 23
A35: 24
A36: 25
A37: 26
A38: 27
A39: 28
A40: 29
A41: 30
A42: 31 | J42: =IF(ISBLANK(I42),"",DATEDIF(I42,$I$9,"Y"))
A43: 32 | J43: =IF(ISBLANK(I43),"",DATEDIF(I43,$I$9,"Y"))
A44: 33 | J44: =IF(ISBLANK(I44),"",DATEDIF(I44,$I$9,"Y"))
A45: 34 | J45: =IF(ISBLANK(I45),"",DATEDIF(I45,$I$9,"Y"))
A46: 35 | J46: =IF(ISBLANK(I46),"",DATEDIF(I46,$I$9,"Y"))
...

Sheet SF2_JUNE
A2: School Form 2 (SF2) Daily Attendance Report of Learners
A3: (This replaces Form 1, Form 2 & STS Form 4 - Absenteeism and Dropout Profile)
G4: 1FBFCVJeD1oNUgr8CQcYAE59bhnLo5qru-QwdKVTqY24
C5: School ID | D5: =SF2_Default!G4 -> 406295 | K5: School Year | L5: =SF2_Default!Q6 -> 2026-2027 | R5: Report for the Month of | Y5: JUNE
C7: Name of School | D7: =SF2_Default!G6 -> MANILA CATHEDRAL SCHOOL | U7: Grade Level | Y7: =SF2_Default!V6 -> Grade 8 | AA7: Section | AI7: =SF2_Default!Y6 -> St. Faustina Kowalska
C9: (Last Name, First Name Middle Name) | E9: JUNE 2026 | AI9: Total for the Month | AK9: REMARKS (If DROPPED OUT, state reason, please refer to legend number 2. If TRANSFERRED IN/OUT, write the name of School.)
B10: ID NUMBER | C10: LEARNER'S NAME | E10: 1 | F10: 2 | G10: 3 | H10: 4 | I10: 5 | K10: 8 | L10: 9 | M10: 10 | N10: 11 | Q10: 15 | R10: 16 | S10: 17 | T10: 18 | U10: 19 | W10: 22 | X10: 23 | Z10: 25 | AA10: 26 | AC10: 29 | AD10: 30 | AI10: ABSENT | AJ10: TARDY
E11: M | F11: T | G11: W | H11: TH | I11: F | J11: S | K11: M | L11: T | M11: W | N11: TH | O11: F | P11: S | Q11: M | R11: T | S11: W | T11: TH | U11: F | V11: S | W11: M | X11: T | Y11: W | Z11: TH | AA11: F | AB11: S | AC11: M | AD11: T | AE11: W | AF11: TH | AG11: F
A12: 1 | B12: =SF2_Default!C12 -> 23-003330 | C12: =SF2_Default!D12 -> BONIFACIO LORD RANI KARL PAINAGA | W12: T | X12: T | AI12: =IF(ISTEXT(C12),COUNTIF(E12:AH12,"X"),"") -> 0 | AJ12: =IF(ISTEXT(C12),COUNTIF(E12:AH12,"T"),"") -> 2
A13: 2 | B13: =SF2_Default!C13 -> 25-001275 | C13: =SF2_Default!D13 -> BUCACAO JOHNREEVE KHARI ALFONSO | M13: X | T13: T | W13: T | Z13: X | AI13: =IF(ISTEXT(C13),COUNTIF(E13:AH13,"X"),"") -> 2 | AJ13: =IF(ISTEXT(C13),COUNTIF(E13:AH13,"T"),"") -> 2
A14: 3 | B14: =SF2_Default!C14 -> 19-00091 | C14: =SF2_Default!D14 -> CANDELARIA JAYREN D | AI14: =IF(ISTEXT(C14),COUNTIF(E14:AH14,"X"),"") -> 0 | AJ14: =IF(ISTEXT(C14),COUNTIF(E14:AH14,"T"),"") -> 0
A15: 4 | B15: =SF2_Default!C15 -> 18-00355 | C15: =SF2_Default!D15 -> CAY ROJER JYUAN P | M15: T | Q15: T | R15: X | S15: T | Z15: X | AI15: =IF(ISTEXT(C15),COUNTIF(E15:AH15,"X"),"") -> 2 | AJ15: =IF(ISTEXT(C15),COUNTIF(E15:AH15,"T"),"") -> 3
A16: 5 | B16: =SF2_Default!C16 -> 25-000460 | C16: =SF2_Default!D16 -> CEZAR JOHN MANUEL DE LEON | S16: T | T16: T | X16: T | AI16: =IF(ISTEXT(C16),COUNTIF(E16:AH16,"X"),"") -> 0 | AJ16: =IF(ISTEXT(C16),COUNTIF(E16:AH16,"T"),"") -> 3
A17: 6 | B17: =SF2_Default!C17 -> 20-00075 | C17: =SF2_Default!D17 -> CONJE LEOBERT JOROS D | X17: X | Z17: X | AI17: =IF(ISTEXT(C17),COUNTIF(E17:AH17,"X"),"") -> 2 | AJ17: =IF(ISTEXT(C17),COUNTIF(E17:AH17,"T"),"") -> 0
A18: 7 | B18: =SF2_Default!C18 -> 25-001588 | C18: =SF2_Default!D18 -> DE LEON MARCUS BRENT TITCO | T18: T | AI18: =IF(ISTEXT(C18),COUNTIF(E18:AH18,"X"),"") -> 0 | AJ18: =IF(ISTEXT(C18),COUNTIF(E18:AH18,"T"),"") -> 1
A19: 8 | B19: =SF2_Default!C19 -> 19-00239 | C19: =SF2_Default!D19 -> DEL ROSARIO ROBIN DALE A | Z19: X | AI19: =IF(ISTEXT(C19),COUNTIF(E19:AH19,"X"),"") -> 1 | AJ19: =IF(ISTEXT(C19),COUNTIF(E19:AH19,"T"),"") -> 0
A20: 9 | B20: =SF2_Default!C20 -> 18-00100 | C20: =SF2_Default!D20 -> DIEGO DAN LEONARD Q | R20: T | W20: X | AI20: =IF(ISTEXT(C20),COUNTIF(E20:AH20,"X"),"") -> 1 | AJ20: =IF(ISTEXT(C20),COUNTIF(E20:AH20,"T"),"") -> 1
A21: 10 | B21: =SF2_Default!C21 -> 19-00097 | C21: =SF2_Default!D21 -> GAMBOA OLIVER FRANCOIS Z | AI21: =IF(ISTEXT(C21),COUNTIF(E21:AH21,"X"),"") -> 0 | AJ21: =IF(ISTEXT(C21),COUNTIF(E21:AH21,"T"),"") -> 0
A22: 11 | B22: =SF2_Default!C22 -> 25-000134 | C22: =SF2_Default!D22 -> GO KELLIN CHASE SAN PEDRO | AI22: =IF(ISTEXT(C22),COUNTIF(E22:AH22,"X"),"") -> 0 | AJ22: =IF(ISTEXT(C22),COUNTIF(E22:AH22,"T"),"") -> 0
A23: 12 | B23: =SF2_Default!C23 -> 25-000839 | C23: =SF2_Default!D23 -> MALINIS ANDREI JAMES PARAGATOS | K23: X | AC23: T | AI23: =IF(ISTEXT(C23),COUNTIF(E23:AH23,"X"),"") -> 1 | AJ23: =IF(ISTEXT(C23),COUNTIF(E23:AH23,"T"),"") -> 1
A24: 13 | B24: =SF2_Default!C24 -> 18-003875 | C24: =SF2_Default!D24 -> PALMA BLAINE XANDER PIMENTEL | Q24: T | S24: T | T24: T | AI24: =IF(ISTEXT(C24),COUNTIF(E24:AH24,"X"),"") -> 0 | AJ24: =IF(ISTEXT(C24),COUNTIF(E24:AH24,"T"),"") -> 3
A25: 14 | B25: =SF2_Default!C25 -> 25-001190 | C25: =SF2_Default!D25 -> POBLETE ARGI CALEB VALENCIA | AI25: =IF(ISTEXT(C25),COUNTIF(E25:AH25,"X"),"") -> 0 | AJ25: =IF(ISTEXT(C25),COUNTIF(E25:AH25,"T"),"") -> 0
A26: 15 | B26: =SF2_Default!C26 -> 25-001123 | C26: =SF2_Default!D26 -> RAVELA RAM JACOB BALDEMOR | M26: T | W26: T | X26: T | AI26: =IF(ISTEXT(C26),COUNTIF(E26:AH26,"X"),"") -> 0 | AJ26: =IF(ISTEXT(C26),COUNTIF(E26:AH26,"T"),"") -> 3
A27: 16 | B27: =SF2_Default!C27 -> 25-001633 | C27: =SF2_Default!D27 -> REYES SHAWN ROWIN VILLAMOR | Q27: X | AC27: T | AI27: =IF(ISTEXT(C27),COUNTIF(E27:AH27,"X"),"") -> 1 | AJ27: =IF(ISTEXT(C27),COUNTIF(E27:AH27,"T"),"") -> 1
A28: 17 | B28: =SF2_Default!C28 -> 25-000718 | C28: =SF2_Default!D28 -> ROBLEDO JOHN MIGUEL SERRANO | AI28: =IF(ISTEXT(C28),COUNTIF(E28:AH28,"X"),"") -> 0 | AJ28: =IF(ISTEXT(C28),COUNTIF(E28:AH28,"T"),"") -> 0
A29: 18 | B29: =SF2_Default!C29 -> 18-003660 | C29: =SF2_Default!D29 -> SACLOLO JUANCHO JAKOB MAGTOTO | AI29: =IF(ISTEXT(C29),COUNTIF(E29:AH29,"X"),"") -> 0 | AJ29: =IF(ISTEXT(C29),COUNTIF(E29:AH29,"T"),"") -> 0
A30: 19 | B30: =SF2_Default!C30 -> 25-001855 | C30: =SF2_Default!D30 -> SALANGSANG DION CARLO DIONISIO | AI30: =IF(ISTEXT(C30),COUNTIF(E30:AH30,"X"),"") -> 0 | AJ30: =IF(ISTEXT(C30),COUNTIF(E30:AH30,"T"),"") -> 0
A31: 20 | B31: =SF2_Default!C31 -> 25-001426 | C31: =SF2_Default!D31 -> SALIGUMBA MAEL CHARLES | AI31: =IF(ISTEXT(C31),COUNTIF(E31:AH31,"X"),"") -> 0 | AJ31: =IF(ISTEXT(C31),COUNTIF(E31:AH31,"T"),"") -> 0
A32: 21 | B32: =SF2_Default!C32 -> 2017-61225 | C32: =SF2_Default!D32 -> TOLENTINO MARCUS CARSTEN B | K32: X | M32: X | Q32: X | S32: X | AI32: =IF(ISTEXT(C32),COUNTIF(E32:AH32,"X"),"") -> 4 | AJ32: =IF(ISTEXT(C32),COUNTIF(E32:AH32,"T"),"") -> 0
A33: 22 | B33: =SF2_Default!C33 -> 0 | C33: =SF2_Default!D33 -> 0 | AI33: =IF(ISTEXT(C33),COUNTIF(E33:AH33,"X"),"") | AJ33: =IF(ISTEXT(C33),COUNTIF(E33:AH33,"T"),"")
A34: 23 | B34: =SF2_Default!C34 -> 0 | C34: =SF2_Default!D34 -> 0 | AI34: =IF(ISTEXT(C34),COUNTIF(E34:AH34,"X"),"") | AJ34: =IF(ISTEXT(C34),COUNTIF(E34:AH34,"T"),"")
A35: 24 | B35: =SF2_Default!C35 -> 0 | C35: =SF2_Default!D35 -> 0 | AI35: =IF(ISTEXT(C35),COUNTIF(E35:AH35,"X"),"") | AJ35: =IF(ISTEXT(C35),COUNTIF(E35:AH35,"T"),"")
A36: 25 | B36: =SF2_Default!C36 -> 0 | C36: =SF2_Default!D36 -> 0 | AI36: =IF(ISTEXT(C36),COUNTIF(E36:AH36,"X"),"") | AJ36: =IF(ISTEXT(C36),COUNTIF(E36:AH36,"T"),"")
A37: 26 | B37: =SF2_Default!C37 -> 0 | C37: =SF2_Default!D37 -> 0 | AI37: =IF(ISTEXT(C37),COUNTIF(E37:AH37,"X"),"") | AJ37: =IF(ISTEXT(C37),COUNTIF(E37:AH37,"T"),"")
A38: 27 | B38: =SF2_Default!C38 -> 0 | C38: =SF2_Default!D38 -> 0 | AI38: =IF(ISTEXT(C38),COUNTIF(E38:AH38,"X"),"") | AJ38: =IF(ISTEXT(C38),COUNTIF(E38:AH38,"T"),"")
A39: 28 | B39: =SF2_Default!C39 -> 0 | C39: =SF2_Default!D39 -> 0 | AI39: =IF(ISTEXT(C39),COUNTIF(E39:AH39,"X"),"") | AJ39: =IF(ISTEXT(C39),COUNTIF(E39:AH39,"T"),"")
A40: 29 | B40: =SF2_Default!C40 -> 0 | C40: =SF2_Default!D40 -> 0 | AI40: =IF(ISTEXT(C40),COUNTIF(E40:AH40,"X"),"") | AJ40: =IF(ISTEXT(C40),COUNTIF(E40:AH40,"T"),"")
A41: 30 | B41: =SF2_Default!C41 -> 0 | C41: =SF2_Default!D41 -> 0 | AI41: =IF(ISTEXT(C41),COUNTIF(E41:AH41,"X"),"") | AJ41: =IF(ISTEXT(C41),COUNTIF(E41:AH41,"T"),"")
A42: 31 | B42: =SF2_Default!C42 -> 0 | C42: =SF2_Default!D42 -> 0 | AI42: =IF(ISTEXT(C42),COUNTIF(E42:AH42,"X"),"") | AJ42: =IF(ISTEXT(C42),COUNTIF(E42:AH42,"T"),"")
A43: 32 | B43: =SF2_Default!C43 -> 0 | C43: =SF2_Default!D43 -> 0 | AI43: =IF(ISTEXT(C43),COUNTIF(E43:AH43,"X"),"") | AJ43: =IF(ISTEXT(C43),COUNTIF(E43:AH43,"T"),"")
...

Sheet SF2_JUL
A2: School Form 2 (SF2) Daily Attendance Report of Learners
A3: (This replaces Form 1, Form 2 & STS Form 4 - Absenteeism and Dropout Profile)
G4: 1FBFCVJeD1oNUgr8CQcYAE59bhnLo5qru-QwdKVTqY24
C5: School ID | D5: =SF2_Default!G4 -> 406295 | K5: School Year | L5: =SF2_Default!Q6 -> 2026-2027 | R5: Report for the Month of | Y5: JULY
C7: Name of School | D7: =SF2_Default!G6 -> MANILA CATHEDRAL SCHOOL | U7: Grade Level | Y7: =SF2_Default!V6 -> Grade 8 | AA7: Section | AI7: =SF2_Default!Y6 -> St. Faustina Kowalska
C9: (Last Name, First Name Middle Name) | E9: JULY 2026 | AI9: Total for the Month | AK9: REMARKS (If DROPPED OUT, state reason, please refer to legend number 2. If TRANSFERRED IN/OUT, write the name of School.)
B10: ID NUMBER | C10: LEARNER'S NAME | G10: 1 | H10: 2 | I10: 3 | K10: 6 | L10: 7 | M10: 8 | N10: 9 | O10: 10 | Q10: 13 | R10: 14 | S10: 15 | T10: 16 | U10: 17 | W10: 20 | X10: 21 | Y10: 22 | Z10: 23 | AA10: 24 | AC10: 27 | AD10: 28 | AE10: 29 | AF10: 30 | AG10: 31 | AI10: ABSENT | AJ10: TARDY
E11: M | F11: T | G11: W | H11: TH | I11: F | J11: S | K11: M | L11: T | M11: W | N11: TH | O11: F | P11: S | Q11: M | R11: T | S11: W | T11: TH | U11: F | V11: S | W11: M | X11: T | Y11: W | Z11: TH | AA11: F | AB11: S | AC11: M | AD11: T | AE11: W | AF11: TH | AG11: F
A12: 1 | B12: =SF2_Default!C12 -> 23-003330 | C12: =SF2_Default!D12 -> BONIFACIO LORD RANI KARL PAINAGA | AI12: =IF(ISTEXT(C12),COUNTIF(E12:AH12,"X"),"") -> 0 | AJ12: =IF(ISTEXT(C12),COUNTIF(E12:AH12,"T"),"") -> 0
A13: 2 | B13: =SF2_Default!C13 -> 25-001275 | C13: =SF2_Default!D13 -> BUCACAO JOHNREEVE KHARI ALFONSO | AI13: =IF(ISTEXT(C13),COUNTIF(E13:AH13,"X"),"") -> 0 | AJ13: =IF(ISTEXT(C13),COUNTIF(E13:AH13,"T"),"") -> 0
A14: 3 | B14: =SF2_Default!C14 -> 19-00091 | C14: =SF2_Default!D14 -> CANDELARIA JAYREN D | AI14: =IF(ISTEXT(C14),COUNTIF(E14:AH14,"X"),"") -> 0 | AJ14: =IF(ISTEXT(C14),COUNTIF(E14:AH14,"T"),"") -> 0
A15: 4 | B15: =SF2_Default!C15 -> 18-00355 | C15: =SF2_Default!D15 -> CAY ROJER JYUAN P | AI15: =IF(ISTEXT(C15),COUNTIF(E15:AH15,"X"),"") -> 0 | AJ15: =IF(ISTEXT(C15),COUNTIF(E15:AH15,"T"),"") -> 0
A16: 5 | B16: =SF2_Default!C16 -> 25-000460 | C16: =SF2_Default!D16 -> CEZAR JOHN MANUEL DE LEON | AI16: =IF(ISTEXT(C16),COUNTIF(E16:AH16,"X"),"") -> 0 | AJ16: =IF(ISTEXT(C16),COUNTIF(E16:AH16,"T"),"") -> 0
A17: 6 | B17: =SF2_Default!C17 -> 20-00075 | C17: =SF2_Default!D17 -> CONJE LEOBERT JOROS D | AI17: =IF(ISTEXT(C17),COUNTIF(E17:AH17,"X"),"") -> 0 | AJ17: =IF(ISTEXT(C17),COUNTIF(E17:AH17,"T"),"") -> 0
A18: 7 | B18: =SF2_Default!C18 -> 25-001588 | C18: =SF2_Default!D18 -> DE LEON MARCUS BRENT TITCO | AI18: =IF(ISTEXT(C18),COUNTIF(E18:AH18,"X"),"") -> 0 | AJ18: =IF(ISTEXT(C18),COUNTIF(E18:AH18,"T"),"") -> 0
A19: 8 | B19: =SF2_Default!C19 -> 19-00239 | C19: =SF2_Default!D19 -> DEL ROSARIO ROBIN DALE A | AI19: =IF(ISTEXT(C19),COUNTIF(E19:AH19,"X"),"") -> 0 | AJ19: =IF(ISTEXT(C19),COUNTIF(E19:AH19,"T"),"") -> 0
A20: 9 | B20: =SF2_Default!C20 -> 18-00100 | C20: =SF2_Default!D20 -> DIEGO DAN LEONARD Q | AI20: =IF(ISTEXT(C20),COUNTIF(E20:AH20,"X"),"") -> 0 | AJ20: =IF(ISTEXT(C20),COUNTIF(E20:AH20,"T"),"") -> 0
A21: 10 | B21: =SF2_Default!C21 -> 19-00097 | C21: =SF2_Default!D21 -> GAMBOA OLIVER FRANCOIS Z | AI21: =IF(ISTEXT(C21),COUNTIF(E21:AH21,"X"),"") -> 0 | AJ21: =IF(ISTEXT(C21),COUNTIF(E21:AH21,"T"),"") -> 0
A22: 11 | B22: =SF2_Default!C22 -> 25-000134 | C22: =SF2_Default!D22 -> GO KELLIN CHASE SAN PEDRO | AI22: =IF(ISTEXT(C22),COUNTIF(E22:AH22,"X"),"") -> 0 | AJ22: =IF(ISTEXT(C22),COUNTIF(E22:AH22,"T"),"") -> 0
A23: 12 | B23: =SF2_Default!C23 -> 25-000839 | C23: =SF2_Default!D23 -> MALINIS ANDREI JAMES PARAGATOS | AI23: =IF(ISTEXT(C23),COUNTIF(E23:AH23,"X"),"") -> 0 | AJ23: =IF(ISTEXT(C23),COUNTIF(E23:AH23,"T"),"") -> 0
... A61: 50 | B61: =SF2_Default!C61 -> 0 | C61: =SF2_Default!D61 -> 0 | AI61: =IF(ISTEXT(C61),COUNTIF(E61:AH61,"X"),"") | AJ61: =IF(ISTEXT(C61),COUNTIF(E61:AH61,"T"),"")
C62: =COUNTIF(C12:C61,"*") -> 21 | E62: =IF(ISNUMBER(E$10),COUNTIF(E12:E61,"X"),"") | F62: =IF(ISNUMBER(F$10),COUNTIF(F12:F61,"X"),"") | G62: =IF(ISNUMBER(G$10),COUNTIF(G12:G61,"X"),"") -> 0 | H62: =IF(ISNUMBER(H$10),COUNTIF(H12:H61,"X"),"") -> 0 | I62: =IF(ISNUMBER(I$10),COUNTIF(I12:I61,"X"),"") -> 0 | J62: =IF(ISNUMBER(J$10),COUNTIF(J12:J61,"X"),"") | K62: =IF(ISNUMBER(K$10),COUNTIF(K12:K61,"X"),"") -> 0 | L62: =IF(ISNUMBER(L$10),COUNTIF(L12:L61,"X"),"") -> 0 | ... AH62: =IF(ISNUMBER(AH$10),COUNTIF(AH12:AH61,"X"),"") | AI62: =SUM(AI12:AI61) -> 0 | AJ62: =SUM(AJ12:AJ61) -> 0
A63: MALE | TOTAL Per Day >>> | E63: =IF(ISNUMBER(E$10),$C$62-E62,"") | F63: =IF(ISNUMBER(F$10),$C$62-F62,"") | G63: =IF(ISNUMBER(G$10),$C$62-G62,"") -> 21 | H63: =IF(ISNUMBER(H$10),$C$62-H62,"") -> 21 | I63: =IF(ISNUMBER(I$10),$C$62-I62,"") -> 21 | J63: =IF(ISNUMBER(J$10),$C$62-J62,"") | K63: =IF(ISNUMBER(K$10),$C$62-K62,"") -> 21 | L63: =IF(ISNUMBER(L$10),$C$62-L62,"") -> 21 | ... AH63: =IF(ISNUMBER(AH$10),$C$62-AH62,"") | AI63: =SUM(E63:AH63) -> 483 | AJ63: <<< Total MALE present for the month
A64: 1 | B64: =SF2_Default!C63 -> 25-000800 | C64: =SF2_Default!D63 -> ANGELES ALLERIA JHANE TUBIANO | AI64: =IF(ISTEXT(C64),COUNTIF(E64:AH64,"X"),"") -> 0 | AJ64: =IF(ISTEXT(C64),COUNTIF(E64:AH64,"T"),"") -> 0
A65: 2 | B65: =SF2_Default!C64 -> 25-001230 | C65: =SF2_Default!D64 -> BELISARIO ELIJAH MIRIONETTE | AI65: =IF(ISTEXT(C65),COUNTIF(E65:AH65,"X"),"") -> 0 | AJ65: =IF(ISTEXT(C65),COUNTIF(E65:AH65,"T"),"") -> 0
A66: 3 | B66: =SF2_Default!C65 -> 18-003636 | C66: =SF2_Default!D65 -> BENEDICTO CASSANDRA VIELLE V | AI66: =IF(ISTEXT(C66),COUNTIF(E66:AH66,"X"),"") -> 0 | AJ66: =IF(ISTEXT(C66),COUNTIF(E66:AH66,"T"),"") -> 0
A67: 4 | B67: =SF2_Default!C66 -> 24-001215 | C67: =SF2_Default!D66 -> BONIFACIO MARY JOICE BONIFACIO | AI67: =IF(ISTEXT(C67),COUNTIF(E67:AH67,"X"),"") -> 0 | AJ67: =IF(ISTEXT(C67),COUNTIF(E67:AH67,"T"),"") -> 0
A68: 5 | B68: =SF2_Default!C67 -> 25-001589 | C68: =SF2_Default!D67 -> CABUSA KYRIE BLAIRE TENERIFE | AI68: =IF(ISTEXT(C68),COUNTIF(E68:AH68,"X"),"") -> 0 | AJ68: =IF(ISTEXT(C68),COUNTIF(E68:AH68,"T"),"") -> 0
A69: 6 | B69: =SF2_Default!C68 -> 22-000390 | C69: =SF2_Default!D68 -> DELA CRUZ BRINA MARCE GATUS | AI69: =IF(ISTEXT(C69),COUNTIF(E69:AH69,"X"),"") -> 0 | AJ69: =IF(ISTEXT(C69),COUNTIF(E69:AH69,"T"),"") -> 0
A70: 7 | B70: =SF2_Default!C69 -> 19-00080 | C70: =SF2_Default!D69 -> DELOS REYES KREEZHA CYLEE D | AI70: =IF(ISTEXT(C70),COUNTIF(E70:AH70,"X"),"") -> 0 | AJ70: =IF(ISTEXT(C70),COUNTIF(E70:AH70,"T"),"") -> 0
A71: 8 | B71: =SF2_Default!C70 -> 19-00075 | C71: =SF2_Default!D70 -> ESCOTO RICH ANNE MARY REYES | AI71: =IF(ISTEXT(C71),COUNTIF(E71:AH71,"X"),"") -> 0 | AJ71: =IF(ISTEXT(C71),COUNTIF(E71:AH71,"T"),"") -> 0
A72: 9 | B72: =SF2_Default!C71 -> 20-00037 | C72: =SF2_Default!D71 -> FORTUNO AZZURIE SOLAYMAN | AI72: =IF(ISTEXT(C72),COUNTIF(E72:AH72,"X"),"") -> 0 | AJ72: =IF(ISTEXT(C72),COUNTIF(E72:AH72,"T"),"") -> 0
A73: 10 | B73: =SF2_Default!C72 -> 25-000884 | C73: =SF2_Default!D72 -> FORTUNO JAYRA VALERIO | AI73: =IF(ISTEXT(C73),COUNTIF(E73:AH73,"X"),"") -> 0 | AJ73: =IF(ISTEXT(C73),COUNTIF(E73:AH73,"T"),"") -> 0
A74: 11 | B74: =SF2_Default!C73 -> 25-001164 | C74: =SF2_Default!D73 -> FUENTES BREEANA KLEIN ALMONIÑA | AI74: =IF(ISTEXT(C74),COUNTIF(E74:AH74,"X"),"") -> 0 | AJ74: =IF(ISTEXT(C74),COUNTIF(E74:AH74,"T"),"") -> 0
A75: 12 | B75: =SF2_Default!C74 -> 25-000191 | C75: =SF2_Default!D74 -> GABUTEN KEISZHA ANDREA ANTIOJO | AI75: =IF(ISTEXT(C75),COUNTIF(E75:AH75,"X"),"") -> 0 | AJ75: =IF(ISTEXT(C75),COUNTIF(E75:AH75,"T"),"") -> 0
... A113: 50 | B113: =SF2_Default!C112 -> 0 | C113: =SF2_Default!D112 -> 0 | AI113: =IF(ISTEXT(C113),COUNTIF(E113:AH113,"X"),"") | AJ113: =IF(ISTEXT(C113),COUNTIF(E113:AH113,"T"),"")
C114: =COUNTIF(C64:C113,"*") -> 22 | E114: =IF(ISNUMBER(E$10),COUNTIF(E64:E113,"X"),"") | F114: =IF(ISNUMBER(F$10),COUNTIF(F64:F113,"X"),"") | G114: =IF(ISNUMBER(G$10),COUNTIF(G64:G113,"X"),"") -> 0 | H114: =IF(ISNUMBER(H$10),COUNTIF(H64:H113,"X"),"") -> 0 | I114: =IF(ISNUMBER(I$10),COUNTIF(I64:I113,"X"),"") -> 0 | J114: =IF(ISNUMBER(J$10),COUNTIF(J64:J113,"X"),"") | K114: =IF(ISNUMBER(K$10),COUNTIF(K64:K113,"X"),"") -> 0 | L114: =IF(ISNUMBER(L$10),COUNTIF(L64:L113,"X"),"") -> 0 | ... AH114: =IF(ISNUMBER(AH$10),COUNTIF(AH64:AH113,"X"),"") | AI114: =SUM(AI64:AI113) -> 0 | AJ114: =SUM(AJ64:AJ113) -> 0
A115: FEMALE | TOTAL Per Day >>> | E115: =IF(ISNUMBER(E$10),$C$114-E114,"") | F115: =IF(ISNUMBER(F$10),$C$114-F114,"") | G115: =IF(ISNUMBER(G$10),$C$114-G114,"") -> 22 | H115: =IF(ISNUMBER(H$10),$C$114-H114,"") -> 22 | I115: =IF(ISNUMBER(I$10),$C$114-I114,"") -> 22 | J115: =IF(ISNUMBER(J$10),$C$114-J114,"") | K115: =IF(ISNUMBER(K$10),$C$114-K114,"") -> 22 | L115: =IF(ISNUMBER(L$10),$C$114-L114,"") -> 22 | ... AH115: =IF(ISNUMBER(AH$10),$C$114-AH114,"") | AI115: =SUM(E115:AH115) -> 506 | AJ115: <<< Total FEMALE present for the month
A116: Combined TOTAL PER DAY | E116: =IF(ISNUMBER(E$10),E63+E115,"") | F116: =IF(ISNUMBER(F$10),F63+F115,"") | G116: =IF(ISNUMBER(G$10),G63+G115,"") -> 43 | H116: =IF(ISNUMBER(H$10),H63+H115,"") -> 43 | I116: =IF(ISNUMBER(I$10),I63+I115,"") -> 43 | J116: =IF(ISNUMBER(J$10),J63+J115,"") | K116: =IF(ISNUMBER(K$10),K63+K115,"") -> 43 | L116: =IF(ISNUMBER(L$10),L63+L115,"") -> 43 | ... AH116: =IF(ISNUMBER(AH$10),AH63+AH115,"") | AI116: =AI63+AI115 -> 989 | AJ116: <<< COMBINED total present for the month
C117: FOOTER
...

Sheet SF2_AUG
A2: School Form 2 (SF2) Daily Attendance Report of Learners
A3: (This replaces Form 1, Form 2 & STS Form 4 - Absenteeism and Dropout Profile)
G4: 1FBFCVJeD1oNUgr8CQcYAE59bhnLo5qru-QwdKVTqY24
C5: School ID | D5: =SF2_Default!G4 -> 406295 | K5: School Year | L5: =SF2_Default!Q6 -> 2026-2027 | R5: Report for the Month of | Y5: AUGUST
C7: Name of School | D7: =SF2_Default!G6 -> MANILA CATHEDRAL SCHOOL | U7: Grade Level | Y7: =SF2_Default!V6 -> Grade 8 | AA7: Section | AI7: =SF2_Default!Y6 -> St. Faustina Kowalska
C9: (Last Name, First Name Middle Name) | E9: AUGUST 2026 | AI9: Total for the Month | AK9: REMARKS (If DROPPED OUT, state reason, please refer to legend number 2. If TRANSFERRED IN/OUT, write the name of School.)
B10: ID NUMBER | C10: LEARNER'S NAME | K10: 3 | L10: 4 | M10: 5 | N10: 6 | O10: 7 | Q10: 10 | R10: 11 | S10: 12 | T10: 13 | U10: 14 | W10: 17 | X10: 18 | Y10: 19 | Z10: 20 | AC10: 24 | AD10: 25 | AE10: 26 | AF10: 27 | AG10: 28 | AI10: ABSENT | AJ10: TARDY
E11: M | F11: T | G11: W | H11: TH | I11: F | J11: S | K11: M | L11: T | M11: W | N11: TH | O11: F | P11: S | Q11: M | R11: T | S11: W | T11: TH | U11: F | V11: S | W11: M | X11: T | Y11: W | Z11: TH | AA11: F | AB11: S | AC11: M | AD11: T | AE11: W | AF11: TH | AG11: F
A12: 1 | B12: =SF2_Default!C12 -> 23-003330 | C12: =SF2_Default!D12 -> BONIFACIO LORD RANI KARL PAINAGA | AI12: =IF(ISTEXT(C12),COUNTIF(E12:AH12,"X"),"") -> 0 | AJ12: =IF(ISTEXT(C12),COUNTIF(E12:AH12,"T"),"") -> 0
A13: 2 | B13: =SF2_Default!C13 -> 25-001275 | C13: =SF2_Default!D13 -> BUCACAO JOHNREEVE KHARI ALFONSO | AI13: =IF(ISTEXT(C13),COUNTIF(E13:AH13,"X"),"") -> 0 | AJ13: =IF(ISTEXT(C13),COUNTIF(E13:AH13,"T"),"") -> 0
A14: 3 | B14: =SF2_Default!C14 -> 19-00091 | C14: =SF2_Default!D14 -> CANDELARIA JAYREN D | AI14: =IF(ISTEXT(C14),COUNTIF(E14:AH14,"X"),"") -> 0 | AJ14: =IF(ISTEXT(C14),COUNTIF(E14:AH14,"T"),"") -> 0
A15: 4 | B15: =SF2_Default!C15 -> 18-00355 | C15: =SF2_Default!D15 -> CAY ROJER JYUAN P | AI15: =IF(ISTEXT(C15),COUNTIF(E15:AH15,"X"),"") -> 0 | AJ15: =IF(ISTEXT(C15),COUNTIF(E15:AH15,"T"),"") -> 0
A16: 5 | B16: =SF2_Default!C16 -> 25-000460 | C16: =SF2_Default!D16 -> CEZAR JOHN MANUEL DE LEON | AI16: =IF(ISTEXT(C16),COUNTIF(E16:AH16,"X"),"") -> 0 | AJ16: =IF(ISTEXT(C16),COUNTIF(E16:AH16,"T"),"") -> 0
A17: 6 | B17: =SF2_Default!C17 -> 20-00075 | C17: =SF2_Default!D17 -> CONJE LEOBERT JOROS D | AI17: =IF(ISTEXT(C17),COUNTIF(E17:AH17,"X"),"") -> 0 | AJ17: =IF(ISTEXT(C17),COUNTIF(E17:AH17,"T"),"") -> 0
A18: 7 | B18: =SF2_Default!C18 -> 25-001588 | C18: =SF2_Default!D18 -> DE LEON MARCUS BRENT TITCO | AI18: =IF(ISTEXT(C18),COUNTIF(E18:AH18,"X"),"") -> 0 | AJ18: =IF(ISTEXT(C18),COUNTIF(E18:AH18,"T"),"") -> 0
A19: 8 | B19: =SF2_Default!C19 -> 19-00239 | C19: =SF2_Default!D19 -> DEL ROSARIO ROBIN DALE A | AI19: =IF(ISTEXT(C19),COUNTIF(E19:AH19,"X"),"") -> 0 | AJ19: =IF(ISTEXT(C19),COUNTIF(E19:AH19,"T"),"") -> 0
A20: 9 | B20: =SF2_Default!C20 -> 18-00100 | C20: =SF2_Default!D20 -> DIEGO DAN LEONARD Q | AI20: =IF(ISTEXT(C20),COUNTIF(E20:AH20,"X"),"") -> 0 | AJ20: =IF(ISTEXT(C20),COUNTIF(E20:AH20,"T"),"") -> 0
A21: 10 | B21: =SF2_Default!C21 -> 19-00097 | C21: =SF2_Default!D21 -> GAMBOA OLIVER FRANCOIS Z | AI21: =IF(ISTEXT(C21),COUNTIF(E21:AH21,"X"),"") -> 0 | AJ21: =IF(ISTEXT(C21),COUNTIF(E21:AH21,"T"),"") -> 0
A22: 11 | B22: =SF2_Default!C22 -> 25-000134 | C22: =SF2_Default!D22 -> GO KELLIN CHASE SAN PEDRO | AI22: =IF(ISTEXT(C22),COUNTIF(E22:AH22,"X"),"") -> 0 | AJ22: =IF(ISTEXT(C22),COUNTIF(E22:AH22,"T"),"") -> 0
A23: 12 | B23: =SF2_Default!C23 -> 25-000839 | C23: =SF2_Default!D23 -> MALINIS ANDREI JAMES PARAGATOS | AI23: =IF(ISTEXT(C23),COUNTIF(E23:AH23,"X"),"") -> 0 | AJ23: =IF(ISTEXT(C23),COUNTIF(E23:AH23,"T"),"") -> 0
... A61: 50 | B61: =SF2_Default!C61 -> 0 | C61: =SF2_Default!D61 -> 0 | AI61: =IF(ISTEXT(C61),COUNTIF(E61:AH61,"X"),"") | AJ61: =IF(ISTEXT(C61),COUNTIF(E61:AH61,"T"),"")
C62: =COUNTIF(C12:C61,"*") -> 21 | E62: =IF(ISNUMBER(E$10),COUNTIF(E12:E61,"X"),"") | F62: =IF(ISNUMBER(F$10),COUNTIF(F12:F61,"X"),"") | G62: =IF(ISNUMBER(G$10),COUNTIF(G12:G61,"X"),"") | H62: =IF(ISNUMBER(H$10),COUNTIF(H12:H61,"X"),"") | I62: =IF(ISNUMBER(I$10),COUNTIF(I12:I61,"X"),"") | J62: =IF(ISNUMBER(J$10),COUNTIF(J12:J61,"X"),"") | K62: =IF(ISNUMBER(K$10),COUNTIF(K12:K61,"X"),"") -> 0 | L62: =IF(ISNUMBER(L$10),COUNTIF(L12:L61,"X"),"") -> 0 | ... AH62: =IF(ISNUMBER(AH$10),COUNTIF(AH12:AH61,"X"),"") | AI62: =SUM(AI12:AI61) -> 0 | AJ62: =SUM(AJ12:AJ61) -> 0
A63: MALE | TOTAL Per Day >>> | E63: =IF(ISNUMBER(E$10),$C$62-E62,"") | F63: =IF(ISNUMBER(F$10),$C$62-F62,"") | G63: =IF(ISNUMBER(G$10),$C$62-G62,"") | H63: =IF(ISNUMBER(H$10),$C$62-H62,"") | I63: =IF(ISNUMBER(I$10),$C$62-I62,"") | J63: =IF(ISNUMBER(J$10),$C$62-J62,"") | K63: =IF(ISNUMBER(K$10),$C$62-K62,"") -> 21 | L63: =IF(ISNUMBER(L$10),$C$62-L62,"") -> 21 | ... AH63: =IF(ISNUMBER(AH$10),$C$62-AH62,"") | AI63: =SUM(E63:AH63) -> 399 | AJ63: <<< Total MALE present for the month
A64: 1 | B64: =SF2_Default!C63 -> 25-000800 | C64: =SF2_Default!D63 -> ANGELES ALLERIA JHANE TUBIANO | AI64: =IF(ISTEXT(C64),COUNTIF(E64:AH64,"X"),"") -> 0 | AJ64: =IF(ISTEXT(C64),COUNTIF(E64:AH64,"T"),"") -> 0
A65: 2 | B65: =SF2_Default!C64 -> 25-001230 | C65: =SF2_Default!D64 -> BELISARIO ELIJAH MIRIONETTE | AI65: =IF(ISTEXT(C65),COUNTIF(E65:AH65,"X"),"") -> 0 | AJ65: =IF(ISTEXT(C65),COUNTIF(E65:AH65,"T"),"") -> 0
A66: 3 | B66: =SF2_Default!C65 -> 18-003636 | C66: =SF2_Default!D65 -> BENEDICTO CASSANDRA VIELLE V | AI66: =IF(ISTEXT(C66),COUNTIF(E66:AH66,"X"),"") -> 0 | AJ66: =IF(ISTEXT(C66),COUNTIF(E66:AH66,"T"),"") -> 0
A67: 4 | B67: =SF2_Default!C66 -> 24-001215 | C67: =SF2_Default!D66 -> BONIFACIO MARY JOICE BONIFACIO | AI67: =IF(ISTEXT(C67),COUNTIF(E67:AH67,"X"),"") -> 0 | AJ67: =IF(ISTEXT(C67),COUNTIF(E67:AH67,"T"),"") -> 0
A68: 5 | B68: =SF2_Default!C67 -> 25-001589 | C68: =SF2_Default!D67 -> CABUSA KYRIE BLAIRE TENERIFE | AI68: =IF(ISTEXT(C68),COUNTIF(E68:AH68,"X"),"") -> 0 | AJ68: =IF(ISTEXT(C68),COUNTIF(E68:AH68,"T"),"") -> 0
A69: 6 | B69: =SF2_Default!C68 -> 22-000390 | C69: =SF2_Default!D68 -> DELA CRUZ BRINA MARCE GATUS | AI69: =IF(ISTEXT(C69),COUNTIF(E69:AH69,"X"),"") -> 0 | AJ69: =IF(ISTEXT(C69),COUNTIF(E69:AH69,"T"),"") -> 0
A70: 7 | B70: =SF2_Default!C69 -> 19-00080 | C70: =SF2_Default!D69 -> DELOS REYES KREEZHA CYLEE D | AI70: =IF(ISTEXT(C70),COUNTIF(E70:AH70,"X"),"") -> 0 | AJ70: =IF(ISTEXT(C70),COUNTIF(E70:AH70,"T"),"") -> 0
A71: 8 | B71: =SF2_Default!C70 -> 19-00075 | C71: =SF2_Default!D70 -> ESCOTO RICH ANNE MARY REYES | AI71: =IF(ISTEXT(C71),COUNTIF(E71:AH71,"X"),"") -> 0 | AJ71: =IF(ISTEXT(C71),COUNTIF(E71:AH71,"T"),"") -> 0
A72: 9 | B72: =SF2_Default!C71 -> 20-00037 | C72: =SF2_Default!D71 -> FORTUNO AZZURIE SOLAYMAN | AI72: =IF(ISTEXT(C72),COUNTIF(E72:AH72,"X"),"") -> 0 | AJ72: =IF(ISTEXT(C72),COUNTIF(E72:AH72,"T"),"") -> 0
A73: 10 | B73: =SF2_Default!C72 -> 25-000884 | C73: =SF2_Default!D72 -> FORTUNO JAYRA VALERIO | AI73: =IF(ISTEXT(C73),COUNTIF(E73:AH73,"X"),"") -> 0 | AJ73: =IF(ISTEXT(C73),COUNTIF(E73:AH73,"T"),"") -> 0
A74: 11 | B74: =SF2_Default!C73 -> 25-001164 | C74: =SF2_Default!D73 -> FUENTES BREEANA KLEIN ALMONIÑA | AI74: =IF(ISTEXT(C74),COUNTIF(E74:AH74,"X"),"") -> 0 | AJ74: =IF(ISTEXT(C74),COUNTIF(E74:AH74,"T"),"") -> 0
A75: 12 | B75: =SF2_Default!C74 -> 25-000191 | C75: =SF2_Default!D74 -> GABUTEN KEISZHA ANDREA ANTIOJO | AI75: =IF(ISTEXT(C75),COUNTIF(E75:AH75,"X"),"") -> 0 | AJ75: =IF(ISTEXT(C75),COUNTIF(E75:AH75,"T"),"") -> 0
... A113: 50 | B113: =SF2_Default!C112 -> 0 | C113: =SF2_Default!D112 -> 0 | AI113: =IF(ISTEXT(C113),COUNTIF(E113:AH113,"X"),"") | AJ113: =IF(ISTEXT(C113),COUNTIF(E113:AH113,"T"),"")
C114: =COUNTIF(C64:C113,"*") -> 22 | E114: =IF(ISNUMBER(E$10),COUNTIF(E64:E113,"X"),"") | F114: =IF(ISNUMBER(F$10),COUNTIF(F64:F113,"X"),"") | G114: =IF(ISNUMBER(G$10),COUNTIF(G64:G113,"X"),"") | H114: =IF(ISNUMBER(H$10),COUNTIF(H64:H113,"X"),"") | I114: =IF(ISNUMBER(I$10),COUNTIF(I64:I113,"X"),"") | J114: =IF(ISNUMBER(J$10),COUNTIF(J64:J113,"X"),"") | K114: =IF(ISNUMBER(K$10),COUNTIF(K64:K113,"X"),"") -> 0 | L114: =IF(ISNUMBER(L$10),COUNTIF(L64:L113,"X"),"") -> 0 | ... AH114: =IF(ISNUMBER(AH$10),COUNTIF(AH64:AH113,"X"),"") | AI114: =SUM(AI64:AI113) -> 0 | AJ114: =SUM(AJ64:AJ113) -> 0
A115: FEMALE | TOTAL Per Day >>> | E115: =IF(ISNUMBER(E$10),$C$114-E114,"") | F115: =IF(ISNUMBER(F$10),$C$114-F114,"") | G115: =IF(ISNUMBER(G$10),$C$114-G114,"") | H115: =IF(ISNUMBER(H$10),$C$114-H114,"") | I115: =IF(ISNUMBER(I$10),$C$114-I114,"") | J115: =IF(ISNUMBER(J$10),$C$114-J114,"") | K115: =IF(ISNUMBER(K$10),$C$114-K114,"") -> 22 | L115: =IF(ISNUMBER(L$10),$C$114-L114,"") -> 22 | ... AH115: =IF(ISNUMBER(AH$10),$C$114-AH114,"") | AI115: =SUM(E115:AH115) -> 418 | AJ115: <<< Total FEMALE present for the month
A116: Combined TOTAL PER DAY | E116: =IF(ISNUMBER(E$10),E63+E115,"") | F116: =IF(ISNUMBER(F$10),F63+F115,"") | G116: =IF(ISNUMBER(G$10),G63+G115,"") | H116: =IF(ISNUMBER(H$10),H63+H115,"") | I116: =IF(ISNUMBER(I$10),I63+I115,"") | J116: =IF(ISNUMBER(J$10),J63+J115,"") | K116: =IF(ISNUMBER(K$10),K63+K115,"") -> 43 | L116: =IF(ISNUMBER(L$10),L63+L115,"") -> 43 | ... AH116: =IF(ISNUMBER(AH$10),AH63+AH115,"") | AI116: =AI63+AI115 -> 817 | AJ116: <<< COMBINED total present for the month
C117: FOOTER
...

Sheet SF2_SEPT
A2: School Form 2 (SF2) Daily Attendance Report of Learners
A3: (This replaces Form 1, Form 2 & STS Form 4 - Absenteeism and Dropout Profile)
G4: 1FBFCVJeD1oNUgr8CQcYAE59bhnLo5qru-QwdKVTqY24
C5: School ID | D5: =SF2_Default!G4 -> 406295 | K5: School Year | L5: =SF2_Default!Q6 -> 2026-2027 | R5: Report for the Month of | Y5: SEPTEMBER
C7: Name of School | D7: =SF2_Default!G6 -> MANILA CATHEDRAL SCHOOL | U7: Grade Level | Y7: =SF2_Default!V6 -> Grade 8 | AA7: Section | AI7: =SF2_Default!Y6 -> St. Faustina Kowalska
C9: (Last Name, First Name Middle Name) | E9: SEPTEMBER 2026 | AI9: Total for the Month | AK9: REMARKS (If DROPPED OUT, state reason, please refer to legend number 2. If TRANSFERRED IN/OUT, write the name of School.)
B10: ID NUMBER | C10: LEARNER'S NAME | F10: 1 | G10: 2 | H10: 3 | I10: 4 | K10: 7 | L10: 8 | M10: 9 | N10: 10 | O10: 11 | Q10: 14 | R10: 15 | S10: 16 | T10: 17 | U10: 18 | W10: 21 | X10: 22 | Y10: 23 | Z10: 24 | AA10: 25 | AC10: 28 | AD10: 29 | AE10: 30 | AI10: ABSENT | AJ10: TARDY
E11: M | F11: T | G11: W | H11: TH | I11: F | J11: S | K11: M | L11: T | M11: W | N11: TH | O11: F | P11: S | Q11: M | R11: T | S11: W | T11: TH | U11: F | V11: S | W11: M | X11: T | Y11: W | Z11: TH | AA11: F | AB11: S | AC11: M | AD11: T | AE11: W | AF11: TH | AG11: F
A12: 1 | B12: =SF2_Default!C12 -> 23-003330 | C12: =SF2_Default!D12 -> BONIFACIO LORD RANI KARL PAINAGA | AI12: =IF(ISTEXT(C12),COUNTIF(E12:AH12,"X"),"") -> 0 | AJ12: =IF(ISTEXT(C12),COUNTIF(E12:AH12,"T"),"") -> 0
A13: 2 | B13: =SF2_Default!C13 -> 25-001275 | C13: =SF2_Default!D13 -> BUCACAO JOHNREEVE KHARI ALFONSO | AI13: =IF(ISTEXT(C13),COUNTIF(E13:AH13,"X"),"") -> 0 | AJ13: =IF(ISTEXT(C13),COUNTIF(E13:AH13,"T"),"") -> 0
A14: 3 | B14: =SF2_Default!C14 -> 19-00091 | C14: =SF2_Default!D14 -> CANDELARIA JAYREN D | AI14: =IF(ISTEXT(C14),COUNTIF(E14:AH14,"X"),"") -> 0 | AJ14: =IF(ISTEXT(C14),COUNTIF(E14:AH14,"T"),"") -> 0
A15: 4 | B15: =SF2_Default!C15 -> 18-00355 | C15: =SF2_Default!D15 -> CAY ROJER JYUAN P | AI15: =IF(ISTEXT(C15),COUNTIF(E15:AH15,"X"),"") -> 0 | AJ15: =IF(ISTEXT(C15),COUNTIF(E15:AH15,"T"),"") -> 0
A16: 5 | B16: =SF2_Default!C16 -> 25-000460 | C16: =SF2_Default!D16 -> CEZAR JOHN MANUEL DE LEON | AI16: =IF(ISTEXT(C16),COUNTIF(E16:AH16,"X"),"") -> 0 | AJ16: =IF(ISTEXT(C16),COUNTIF(E16:AH16,"T"),"") -> 0
A17: 6 | B17: =SF2_Default!C17 -> 20-00075 | C17: =SF2_Default!D17 -> CONJE LEOBERT JOROS D | AI17: =IF(ISTEXT(C17),COUNTIF(E17:AH17,"X"),"") -> 0 | AJ17: =IF(ISTEXT(C17),COUNTIF(E17:AH17,"T"),"") -> 0
A18: 7 | B18: =SF2_Default!C18 -> 25-001588 | C18: =SF2_Default!D18 -> DE LEON MARCUS BRENT TITCO | AI18: =IF(ISTEXT(C18),COUNTIF(E18:AH18,"X"),"") -> 0 | AJ18: =IF(ISTEXT(C18),COUNTIF(E18:AH18,"T"),"") -> 0
A19: 8 | B19: =SF2_Default!C19 -> 19-00239 | C19: =SF2_Default!D19 -> DEL ROSARIO ROBIN DALE A | AI19: =IF(ISTEXT(C19),COUNTIF(E19:AH19,"X"),"") -> 0 | AJ19: =IF(ISTEXT(C19),COUNTIF(E19:AH19,"T"),"") -> 0
A20: 9 | B20: =SF2_Default!C20 -> 18-00100 | C20: =SF2_Default!D20 -> DIEGO DAN LEONARD Q | AI20: =IF(ISTEXT(C20),COUNTIF(E20:AH20,"X"),"") -> 0 | AJ20: =IF(ISTEXT(C20),COUNTIF(E20:AH20,"T"),"") -> 0
A21: 10 | B21: =SF2_Default!C21 -> 19-00097 | C21: =SF2_Default!D21 -> GAMBOA OLIVER FRANCOIS Z | AI21: =IF(ISTEXT(C21),COUNTIF(E21:AH21,"X"),"") -> 0 | AJ21: =IF(ISTEXT(C21),COUNTIF(E21:AH21,"T"),"") -> 0
A22: 11 | B22: =SF2_Default!C22 -> 25-000134 | C22: =SF2_Default!D22 -> GO KELLIN CHASE SAN PEDRO | AI22: =IF(ISTEXT(C22),COUNTIF(E22:AH22,"X"),"") -> 0 | AJ22: =IF(ISTEXT(C22),COUNTIF(E22:AH22,"T"),"") -> 0
A23: 12 | B23: =SF2_Default!C23 -> 25-000839 | C23: =SF2_Default!D23 -> MALINIS ANDREI JAMES PARAGATOS | AI23: =IF(ISTEXT(C23),COUNTIF(E23:AH23,"X"),"") -> 0 | AJ23: =IF(ISTEXT(C23),COUNTIF(E23:AH23,"T"),"") -> 0
... A61: 50 | B61: =SF2_Default!C61 -> 0 | C61: =SF2_Default!D61 -> 0 | AI61: =IF(ISTEXT(C61),COUNTIF(E61:AH61,"X"),"") | AJ61: =IF(ISTEXT(C61),COUNTIF(E61:AH61,"T"),"")
C62: =COUNTIF(C12:C61,"*") -> 21 | E62: =IF(ISNUMBER(E$10),COUNTIF(E12:E61,"X"),"") | F62: =IF(ISNUMBER(F$10),COUNTIF(F12:F61,"X"),"") -> 0 | G62: =IF(ISNUMBER(G$10),COUNTIF(G12:G61,"X"),"") -> 0 | H62: =IF(ISNUMBER(H$10),COUNTIF(H12:H61,"X"),"") -> 0 | I62: =IF(ISNUMBER(I$10),COUNTIF(I12:I61,"X"),"") -> 0 | J62: =IF(ISNUMBER(J$10),COUNTIF(J12:J61,"X"),"") | K62: =IF(ISNUMBER(K$10),COUNTIF(K12:K61,"X"),"") -> 0 | L62: =IF(ISNUMBER(L$10),COUNTIF(L12:L61,"X"),"") -> 0 | ... AH62: =IF(ISNUMBER(AH$10),COUNTIF(AH12:AH61,"X"),"") | AI62: =SUM(AI12:AI61) -> 0 | AJ62: =SUM(AJ12:AJ61) -> 0
A63: MALE | TOTAL Per Day >>> | E63: =IF(ISNUMBER(E$10),$C$62-E62,"") | F63: =IF(ISNUMBER(F$10),$C$62-F62,"") -> 21 | G63: =IF(ISNUMBER(G$10),$C$62-G62,"") -> 21 | H63: =IF(ISNUMBER(H$10),$C$62-H62,"") -> 21 | I63: =IF(ISNUMBER(I$10),$C$62-I62,"") -> 21 | J63: =IF(ISNUMBER(J$10),$C$62-J62,"") | K63: =IF(ISNUMBER(K$10),$C$62-K62,"") -> 21 | L63: =IF(ISNUMBER(L$10),$C$62-L62,"") -> 21 | ... AH63: =IF(ISNUMBER(AH$10),$C$62-AH62,"") | AI63: =SUM(E63:AH63) -> 462 | AJ63: <<< Total MALE present for the month
A64: 1 | B64: =SF2_Default!C63 -> 25-000800 | C64: =SF2_Default!D63 -> ANGELES ALLERIA JHANE TUBIANO | AI64: =IF(ISTEXT(C64),COUNTIF(E64:AH64,"X"),"") -> 0 | AJ64: =IF(ISTEXT(C64),COUNTIF(E64:AH64,"T"),"") -> 0
A65: 2 | B65: =SF2_Default!C64 -> 25-001230 | C65: =SF2_Default!D64 -> BELISARIO ELIJAH MIRIONETTE | AI65: =IF(ISTEXT(C65),COUNTIF(E65:AH65,"X"),"") -> 0 | AJ65: =IF(ISTEXT(C65),COUNTIF(E65:AH65,"T"),"") -> 0
A66: 3 | B66: =SF2_Default!C65 -> 18-003636 | C66: =SF2_Default!D65 -> BENEDICTO CASSANDRA VIELLE V | AI66: =IF(ISTEXT(C66),COUNTIF(E66:AH66,"X"),"") -> 0 | AJ66: =IF(ISTEXT(C66),COUNTIF(E66:AH66,"T"),"") -> 0
A67: 4 | B67: =SF2_Default!C66 -> 24-001215 | C67: =SF2_Default!D66 -> BONIFACIO MARY JOICE BONIFACIO | AI67: =IF(ISTEXT(C67),COUNTIF(E67:AH67,"X"),"") -> 0 | AJ67: =IF(ISTEXT(C67),COUNTIF(E67:AH67,"T"),"") -> 0
A68: 5 | B68: =SF2_Default!C67 -> 25-001589 | C68: =SF2_Default!D67 -> CABUSA KYRIE BLAIRE TENERIFE | AI68: =IF(ISTEXT(C68),COUNTIF(E68:AH68,"X"),"") -> 0 | AJ68: =IF(ISTEXT(C68),COUNTIF(E68:AH68,"T"),"") -> 0
A69: 6 | B69: =SF2_Default!C68 -> 22-000390 | C69: =SF2_Default!D68 -> DELA CRUZ BRINA MARCE GATUS | AI69: =IF(ISTEXT(C69),COUNTIF(E69:AH69,"X"),"") -> 0 | AJ69: =IF(ISTEXT(C69),COUNTIF(E69:AH69,"T"),"") -> 0
A70: 7 | B70: =SF2_Default!C69 -> 19-00080 | C70: =SF2_Default!D69 -> DELOS REYES KREEZHA CYLEE D | AI70: =IF(ISTEXT(C70),COUNTIF(E70:AH70,"X"),"") -> 0 | AJ70: =IF(ISTEXT(C70),COUNTIF(E70:AH70,"T"),"") -> 0
A71: 8 | B71: =SF2_Default!C70 -> 19-00075 | C71: =SF2_Default!D70 -> ESCOTO RICH ANNE MARY REYES | AI71: =IF(ISTEXT(C71),COUNTIF(E71:AH71,"X"),"") -> 0 | AJ71: =IF(ISTEXT(C71),COUNTIF(E71:AH71,"T"),"") -> 0
A72: 9 | B72: =SF2_Default!C71 -> 20-00037 | C72: =SF2_Default!D71 -> FORTUNO AZZURIE SOLAYMAN | AI72: =IF(ISTEXT(C72),COUNTIF(E72:AH72,"X"),"") -> 0 | AJ72: =IF(ISTEXT(C72),COUNTIF(E72:AH72,"T"),"") -> 0
A73: 10 | B73: =SF2_Default!C72 -> 25-000884 | C73: =SF2_Default!D72 -> FORTUNO JAYRA VALERIO | AI73: =IF(ISTEXT(C73),COUNTIF(E73:AH73,"X"),"") -> 0 | AJ73: =IF(ISTEXT(C73),COUNTIF(E73:AH73,"T"),"") -> 0
A74: 11 | B74: =SF2_Default!C73 -> 25-001164 | C74: =SF2_Default!D73 -> FUENTES BREEANA KLEIN ALMONIÑA | AI74: =IF(ISTEXT(C74),COUNTIF(E74:AH74,"X"),"") -> 0 | AJ74: =IF(ISTEXT(C74),COUNTIF(E74:AH74,"T"),"") -> 0
A75: 12 | B75: =SF2_Default!C74 -> 25-000191 | C75: =SF2_Default!D74 -> GABUTEN KEISZHA ANDREA ANTIOJO | AI75: =IF(ISTEXT(C75),COUNTIF(E75:AH75,"X"),"") -> 0 | AJ75: =IF(ISTEXT(C75),COUNTIF(E75:AH75,"T"),"") -> 0
... A113: 50 | B113: =SF2_Default!C112 -> 0 | C113: =SF2_Default!D112 -> 0 | AI113: =IF(ISTEXT(C113),COUNTIF(E113:AH113,"X"),"") | AJ113: =IF(ISTEXT(C113),COUNTIF(E113:AH113,"T"),"")
C114: =COUNTIF(C64:C113,"*") -> 22 | E114: =IF(ISNUMBER(E$10),COUNTIF(E64:E113,"X"),"") | F114: =IF(ISNUMBER(F$10),COUNTIF(F64:F113,"X"),"") -> 0 | G114: =IF(ISNUMBER(G$10),COUNTIF(G64:G113,"X"),"") -> 0 | H114: =IF(ISNUMBER(H$10),COUNTIF(H64:H113,"X"),"") -> 0 | I114: =IF(ISNUMBER(I$10),COUNTIF(I64:I113,"X"),"") -> 0 | J114: =IF(ISNUMBER(J$10),COUNTIF(J64:J113,"X"),"") | K114: =IF(ISNUMBER(K$10),COUNTIF(K64:K113,"X"),"") -> 0 | L114: =IF(ISNUMBER(L$10),COUNTIF(L64:L113,"X"),"") -> 0 | ... AH114: =IF(ISNUMBER(AH$10),COUNTIF(AH64:AH113,"X"),"") | AI114: =SUM(AI64:AI113) -> 0 | AJ114: =SUM(AJ64:AJ113) -> 0
A115: FEMALE | TOTAL Per Day >>> | E115: =IF(ISNUMBER(E$10),$C$114-E114,"") | F115: =IF(ISNUMBER(F$10),$C$114-F114,"") -> 22 | G115: =IF(ISNUMBER(G$10),$C$114-G114,"") -> 22 | H115: =IF(ISNUMBER(H$10),$C$114-H114,"") -> 22 | I115: =IF(ISNUMBER(I$10),$C$114-I114,"") -> 22 | J115: =IF(ISNUMBER(J$10),$C$114-J114,"") | K115: =IF(ISNUMBER(K$10),$C$114-K114,"") -> 22 | L115: =IF(ISNUMBER(L$10),$C$114-L114,"") -> 22 | ... AH115: =IF(ISNUMBER(AH$10),$C$114-AH114,"") | AI115: =SUM(E115:AH115) -> 484 | AJ115: <<< Total FEMALE present for the month
A116: Combined TOTAL PER DAY | E116: =IF(ISNUMBER(E$10),E63+E115,"") | F116: =IF(ISNUMBER(F$10),F63+F115,"") -> 43 | G116: =IF(ISNUMBER(G$10),G63+G115,"") -> 43 | H116: =IF(ISNUMBER(H$10),H63+H115,"") -> 43 | I116: =IF(ISNUMBER(I$10),I63+I115,"") -> 43 | J116: =IF(ISNUMBER(J$10),J63+J115,"") | K116: =IF(ISNUMBER(K$10),K63+K115,"") -> 43 | L116: =IF(ISNUMBER(L$10),L63+L115,"") -> 43 | ... AH116: =IF(ISNUMBER(AH$10),AH63+AH115,"") | AI116: =AI63+AI115 -> 946 | AJ116: <<< COMBINED total present for the month
C117: FOOTER
...

Sheet SF2_OCT
A2: School Form 2 (SF2) Daily Attendance Report of Learners
A3: (This replaces Form 1, Form 2 & STS Form 4 - Absenteeism and Dropout Profile)
G4: 1FBFCVJeD1oNUgr8CQcYAE59bhnLo5qru-QwdKVTqY24
C5: School ID | D5: =SF2_Default!G4 -> 406295 | K5: School Year | L5: =SF2_Default!Q6 -> 2026-2027 | R5: Report for the Month of | Y5: OCTOBER
C7: Name of School | D7: =SF2_Default!G6 -> MANILA CATHEDRAL SCHOOL | U7: Grade Level | Y7: =SF2_Default!V6 -> Grade 8 | AA7: Section | AI7: =SF2_Default!Y6 -> St. Faustina Kowalska
C9: (Last Name, First Name Middle Name) | E9: OCTOBER 2026 | AI9: Total for the Month | AK9: REMARKS (If DROPPED OUT, state reason, please refer to legend number 2. If TRANSFERRED IN/OUT, write the name of School.)
B10: ID NUMBER | C10: LEARNER'S NAME | H10: 1 | I10: 2 | K10: 5 | L10: 6 | M10: 7 | N10: 8 | O10: 9 | Q10: 12 | R10: 13 | S10: 14 | T10: 15 | U10: 16 | W10: 19 | X10: 20 | Y10: 21 | Z10: 22 | AA10: 23 | AC10: 26 | AD10: 27 | AE10: 28 | AF10: 29 | AG10: 30 | AI10: ABSENT | AJ10: TARDY
E11: M | F11: T | G11: W | H11: TH | I11: F | J11: S | K11: M | L11: T | M11: W | N11: TH | O11: F | P11: S | Q11: M | R11: T | S11: W | T11: TH | U11: F | V11: S | W11: M | X11: T | Y11: W | Z11: TH | AA11: F | AB11: S | AC11: M | AD11: T | AE11: W | AF11: TH | AG11: F
A12: 1 | B12: =SF2_Default!C12 -> 23-003330 | C12: =SF2_Default!D12 -> BONIFACIO LORD RANI KARL PAINAGA | AI12: =IF(ISTEXT(C12),COUNTIF(E12:AH12,"X"),"") -> 0 | AJ12: =IF(ISTEXT(C12),COUNTIF(E12:AH12,"T"),"") -> 0
A13: 2 | B13: =SF2_Default!C13 -> 25-001275 | C13: =SF2_Default!D13 -> BUCACAO JOHNREEVE KHARI ALFONSO | AI13: =IF(ISTEXT(C13),COUNTIF(E13:AH13,"X"),"") -> 0 | AJ13: =IF(ISTEXT(C13),COUNTIF(E13:AH13,"T"),"") -> 0
A14: 3 | B14: =SF2_Default!C14 -> 19-00091 | C14: =SF2_Default!D14 -> CANDELARIA JAYREN D | AI14: =IF(ISTEXT(C14),COUNTIF(E14:AH14,"X"),"") -> 0 | AJ14: =IF(ISTEXT(C14),COUNTIF(E14:AH14,"T"),"") -> 0
A15: 4 | B15: =SF2_Default!C15 -> 18-00355 | C15: =SF2_Default!D15 -> CAY ROJER JYUAN P | AI15: =IF(ISTEXT(C15),COUNTIF(E15:AH15,"X"),"") -> 0 | AJ15: =IF(ISTEXT(C15),COUNTIF(E15:AH15,"T"),"") -> 0
A16: 5 | B16: =SF2_Default!C16 -> 25-000460 | C16: =SF2_Default!D16 -> CEZAR JOHN MANUEL DE LEON | AI16: =IF(ISTEXT(C16),COUNTIF(E16:AH16,"X"),"") -> 0 | AJ16: =IF(ISTEXT(C16),COUNTIF(E16:AH16,"T"),"") -> 0
A17: 6 | B17: =SF2_Default!C17 -> 20-00075 | C17: =SF2_Default!D17 -> CONJE LEOBERT JOROS D | AI17: =IF(ISTEXT(C17),COUNTIF(E17:AH17,"X"),"") -> 0 | AJ17: =IF(ISTEXT(C17),COUNTIF(E17:AH17,"T"),"") -> 0
A18: 7 | B18: =SF2_Default!C18 -> 25-001588 | C18: =SF2_Default!D18 -> DE LEON MARCUS BRENT TITCO | AI18: =IF(ISTEXT(C18),COUNTIF(E18:AH18,"X"),"") -> 0 | AJ18: =IF(ISTEXT(C18),COUNTIF(E18:AH18,"T"),"") -> 0
A19: 8 | B19: =SF2_Default!C19 -> 19-00239 | C19: =SF2_Default!D19 -> DEL ROSARIO ROBIN DALE A | AI19: =IF(ISTEXT(C19),COUNTIF(E19:AH19,"X"),"") -> 0 | AJ19: =IF(ISTEXT(C19),COUNTIF(E19:AH19,"T"),"") -> 0
A20: 9 | B20: =SF2_Default!C20 -> 18-00100 | C20: =SF2_Default!D20 -> DIEGO DAN LEONARD Q | AI20: =IF(ISTEXT(C20),COUNTIF(E20:AH20,"X"),"") -> 0 | AJ20: =IF(ISTEXT(C20),COUNTIF(E20:AH20,"T"),"") -> 0
A21: 10 | B21: =SF2_Default!C21 -> 19-00097 | C21: =SF2_Default!D21 -> GAMBOA OLIVER FRANCOIS Z | AI21: =IF(ISTEXT(C21),COUNTIF(E21:AH21,"X"),"") -> 0 | AJ21: =IF(ISTEXT(C21),COUNTIF(E21:AH21,"T"),"") -> 0
A22: 11 | B22: =SF2_Default!C22 -> 25-000134 | C22: =SF2_Default!D22 -> GO KELLIN CHASE SAN PEDRO | AI22: =IF(ISTEXT(C22),COUNTIF(E22:AH22,"X"),"") -> 0 | AJ22: =IF(ISTEXT(C22),COUNTIF(E22:AH22,"T"),"") -> 0
A23: 12 | B23: =SF2_Default!C23 -> 25-000839 | C23: =SF2_Default!D23 -> MALINIS ANDREI JAMES PARAGATOS | AI23: =IF(ISTEXT(C23),COUNTIF(E23:AH23,"X"),"") -> 0 | AJ23: =IF(ISTEXT(C23),COUNTIF(E23:AH23,"T"),"") -> 0
... A61: 50 | B61: =SF2_Default!C61 -> 0 | C61: =SF2_Default!D61 -> 0 | AI61: =IF(ISTEXT(C61),COUNTIF(E61:AH61,"X"),"") | AJ61: =IF(ISTEXT(C61),COUNTIF(E61:AH61,"T"),"")
C62: =COUNTIF(C12:C61,"*") -> 21 | E62: =IF(ISNUMBER(E$10),COUNTIF(E12:E61,"X"),"") | F62: =IF(ISNUMBER(F$10),COUNTIF(F12:F61,"X"),"") | G62: =IF(ISNUMBER(G$10),COUNTIF(G12:G61,"X"),"") | H62: =IF(ISNUMBER(H$10),COUNTIF(H12:H61,"X"),"") -> 0 | I62: =IF(ISNUMBER(I$10),COUNTIF(I12:I61,"X"),"") -> 0 | J62: =IF(ISNUMBER(J$10),COUNTIF(J12:J61,"X"),"") | K62: =IF(ISNUMBER(K$10),COUNTIF(K12:K61,"X"),"") -> 0 | L62: =IF(ISNUMBER(L$10),COUNTIF(L12:L61,"X"),"") -> 0 | ... AH62: =IF(ISNUMBER(AH$10),COUNTIF(AH12:AH61,"X"),"") | AI62: =SUM(AI12:AI61) -> 0 | AJ62: =SUM(AJ12:AJ61) -> 0
A63: MALE | TOTAL Per Day >>> | E63: =IF(ISNUMBER(E$10),$C$62-E62,"") | F63: =IF(ISNUMBER(F$10),$C$62-F62,"") | G63: =IF(ISNUMBER(G$10),$C$62-G62,"") | H63: =IF(ISNUMBER(H$10),$C$62-H62,"") -> 21 | I63: =IF(ISNUMBER(I$10),$C$62-I62,"") -> 21 | J63: =IF(ISNUMBER(J$10),$C$62-J62,"") | K63: =IF(ISNUMBER(K$10),$C$62-K62,"") -> 21 | L63: =IF(ISNUMBER(L$10),$C$62-L62,"") -> 21 | ... AH63: =IF(ISNUMBER(AH$10),$C$62-AH62,"") | AI63: =SUM(E63:AH63) -> 462 | AJ63: <<< Total MALE present for the month
A64: 1 | B64: =SF2_Default!C63 -> 25-000800 | C64: =SF2_Default!D63 -> ANGELES ALLERIA JHANE TUBIANO | AI64: =IF(ISTEXT(C64),COUNTIF(E64:AH64,"X"),"") -> 0 | AJ64: =IF(ISTEXT(C64),COUNTIF(E64:AH64,"T"),"") -> 0
A65: 2 | B65: =SF2_Default!C64 -> 25-001230 | C65: =SF2_Default!D64 -> BELISARIO ELIJAH MIRIONETTE | AI65: =IF(ISTEXT(C65),COUNTIF(E65:AH65,"X"),"") -> 0 | AJ65: =IF(ISTEXT(C65),COUNTIF(E65:AH65,"T"),"") -> 0
A66: 3 | B66: =SF2_Default!C65 -> 18-003636 | C66: =SF2_Default!D65 -> BENEDICTO CASSANDRA VIELLE V | AI66: =IF(ISTEXT(C66),COUNTIF(E66:AH66,"X"),"") -> 0 | AJ66: =IF(ISTEXT(C66),COUNTIF(E66:AH66,"T"),"") -> 0
A67: 4 | B67: =SF2_Default!C66 -> 24-001215 | C67: =SF2_Default!D66 -> BONIFACIO MARY JOICE BONIFACIO | AI67: =IF(ISTEXT(C67),COUNTIF(E67:AH67,"X"),"") -> 0 | AJ67: =IF(ISTEXT(C67),COUNTIF(E67:AH67,"T"),"") -> 0
A68: 5 | B68: =SF2_Default!C67 -> 25-001589 | C68: =SF2_Default!D67 -> CABUSA KYRIE BLAIRE TENERIFE | AI68: =IF(ISTEXT(C68),COUNTIF(E68:AH68,"X"),"") -> 0 | AJ68: =IF(ISTEXT(C68),COUNTIF(E68:AH68,"T"),"") -> 0
A69: 6 | B69: =SF2_Default!C68 -> 22-000390 | C69: =SF2_Default!D68 -> DELA CRUZ BRINA MARCE GATUS | AI69: =IF(ISTEXT(C69),COUNTIF(E69:AH69,"X"),"") -> 0 | AJ69: =IF(ISTEXT(C69),COUNTIF(E69:AH69,"T"),"") -> 0
A70: 7 | B70: =SF2_Default!C69 -> 19-00080 | C70: =SF2_Default!D69 -> DELOS REYES KREEZHA CYLEE D | AI70: =IF(ISTEXT(C70),COUNTIF(E70:AH70,"X"),"") -> 0 | AJ70: =IF(ISTEXT(C70),COUNTIF(E70:AH70,"T"),"") -> 0
A71: 8 | B71: =SF2_Default!C70 -> 19-00075 | C71: =SF2_Default!D70 -> ESCOTO RICH ANNE MARY REYES | AI71: =IF(ISTEXT(C71),COUNTIF(E71:AH71,"X"),"") -> 0 | AJ71: =IF(ISTEXT(C71),COUNTIF(E71:AH71,"T"),"") -> 0
A72: 9 | B72: =SF2_Default!C71 -> 20-00037 | C72: =SF2_Default!D71 -> FORTUNO AZZURIE SOLAYMAN | AI72: =IF(ISTEXT(C72),COUNTIF(E72:AH72,"X"),"") -> 0 | AJ72: =IF(ISTEXT(C72),COUNTIF(E72:AH72,"T"),"") -> 0
A73: 10 | B73: =SF2_Default!C72 -> 25-000884 | C73: =SF2_Default!D72 -> FORTUNO JAYRA VALERIO | AI73: =IF(ISTEXT(C73),COUNTIF(E73:AH73,"X"),"") -> 0 | AJ73: =IF(ISTEXT(C73),COUNTIF(E73:AH73,"T"),"") -> 0
A74: 11 | B74: =SF2_Default!C73 -> 25-001164 | C74: =SF2_Default!D73 -> FUENTES BREEANA KLEIN ALMONIÑA | AI74: =IF(ISTEXT(C74),COUNTIF(E74:AH74,"X"),"") -> 0 | AJ74: =IF(ISTEXT(C74),COUNTIF(E74:AH74,"T"),"") -> 0
A75: 12 | B75: =SF2_Default!C74 -> 25-000191 | C75: =SF2_Default!D74 -> GABUTEN KEISZHA ANDREA ANTIOJO | AI75: =IF(ISTEXT(C75),COUNTIF(E75:AH75,"X"),"") -> 0 | AJ75: =IF(ISTEXT(C75),COUNTIF(E75:AH75,"T"),"") -> 0
... A113: 50 | B113: =SF2_Default!C112 -> 0 | C113: =SF2_Default!D112 -> 0 | AI113: =IF(ISTEXT(C113),COUNTIF(E113:AH113,"X"),"") | AJ113: =IF(ISTEXT(C113),COUNTIF(E113:AH113,"T"),"")
C114: =COUNTIF(C64:C113,"*") -> 22 | E114: =IF(ISNUMBER(E$10),COUNTIF(E64:E113,"X"),"") | F114: =IF(ISNUMBER(F$10),COUNTIF(F64:F113,"X"),"") | G114: =IF(ISNUMBER(G$10),COUNTIF(G64:G113,"X"),"") | H114: =IF(ISNUMBER(H$10),COUNTIF(H64:H113,"X"),"") -> 0 | I114: =IF(ISNUMBER(I$10),COUNTIF(I64:I113,"X"),"") -> 0 | J114: =IF(ISNUMBER(J$10),COUNTIF(J64:J113,"X"),"") | K114: =IF(ISNUMBER(K$10),COUNTIF(K64:K113,"X"),"") -> 0 | L114: =IF(ISNUMBER(L$10),COUNTIF(L64:L113,"X"),"") -> 0 | ... AH114: =IF(ISNUMBER(AH$10),COUNTIF(AH64:AH113,"X"),"") | AI114: =SUM(AI64:AI113) -> 0 | AJ114: =SUM(AJ64:AJ113) -> 0
A115: FEMALE | TOTAL Per Day >>> | E115: =IF(ISNUMBER(E$10),$C$114-E114,"") | F115: =IF(ISNUMBER(F$10),$C$114-F114,"") | G115: =IF(ISNUMBER(G$10),$C$114-G114,"") | H115: =IF(ISNUMBER(H$10),$C$114-H114,"") -> 22 | I115: =IF(ISNUMBER(I$10),$C$114-I114,"") -> 22 | J115: =IF(ISNUMBER(J$10),$C$114-J114,"") | K115: =IF(ISNUMBER(K$10),$C$114-K114,"") -> 22 | L115: =IF(ISNUMBER(L$10),$C$114-L114,"") -> 22 | ... AH115: =IF(ISNUMBER(AH$10),$C$114-AH114,"") | AI115: =SUM(E115:AH115) -> 484 | AJ115: <<< Total FEMALE present for the month
A116: Combined TOTAL PER DAY | E116: =IF(ISNUMBER(E$10),E63+E115,"") | F116: =IF(ISNUMBER(F$10),F63+F115,"") | G116: =IF(ISNUMBER(G$10),G63+G115,"") | H116: =IF(ISNUMBER(H$10),H63+H115,"") -> 43 | I116: =IF(ISNUMBER(I$10),I63+I115,"") -> 43 | J116: =IF(ISNUMBER(J$10),J63+J115,"") | K116: =IF(ISNUMBER(K$10),K63+K115,"") -> 43 | L116: =IF(ISNUMBER(L$10),L63+L115,"") -> 43 | ... AH116: =IF(ISNUMBER(AH$10),AH63+AH115,"") | AI116: =AI63+AI115 -> 946 | AJ116: <<< COMBINED total present for the month
C117: FOOTER
...

Sheet SF2_NOV
A2: School Form 2 (SF2) Daily Attendance Report of Learners
A3: (This replaces Form 1, Form 2 & STS Form 4 - Absenteeism and Dropout Profile)
G4: 1FBFCVJeD1oNUgr8CQcYAE59bhnLo5qru-QwdKVTqY24
C5: School ID | D5: =SF2_Default!G4 -> 406295 | K5: School Year | L5: =SF2_Default!Q6 -> 2026-2027 | R5: Report for the Month of | Y5: NOVEMBER
C7: Name of School | D7: =SF2_Default!G6 -> MANILA CATHEDRAL SCHOOL | U7: Grade Level | Y7: =SF2_Default!V6 -> Grade 8 | AA7: Section | AI7: =SF2_Default!Y6 -> St. Faustina Kowalska
C9: (Last Name, First Name Middle Name) | E9: NOVEMBER 2026 | AI9: Total for the Month | AK9: REMARKS (If DROPPED OUT, state reason, please refer to legend number 2. If TRANSFERRED IN/OUT, write the name of School.)
B10: ID NUMBER | C10: LEARNER'S NAME | K10: 9 | L10: 10 | M10: 11 | N10: 12 | O10: 13 | P10: 14 | Q10: 16 | R10: 17 | S10: 18 | T10: 19 | U10: 20 | W10: 23 | X10: 24 | Y10: 25 | Z10: 26 | AA10: 27 | AI10: ABSENT | AJ10: TARDY
E11: M | F11: T | G11: W | H11: TH | I11: F | J11: S | K11: M | L11: T | M11: W | N11: TH | O11: F | P11: S | Q11: M | R11: T | S11: W | T11: TH | U11: F | V11: S | W11: M | X11: T | Y11: W | Z11: TH | AA11: F | AB11: S | AC11: M | AD11: T | AE11: W | AF11: TH | AG11: F
A12: 1 | B12: =SF2_Default!C12 -> 23-003330 | C12: =SF2_Default!D12 -> BONIFACIO LORD RANI KARL PAINAGA | AI12: =IF(ISTEXT(C12),COUNTIF(E12:AH12,"X"),"") -> 0 | AJ12: =IF(ISTEXT(C12),COUNTIF(E12:AH12,"T"),"") -> 0
A13: 2 | B13: =SF2_Default!C13 -> 25-001275 | C13: =SF2_Default!D13 -> BUCACAO JOHNREEVE KHARI ALFONSO | AI13: =IF(ISTEXT(C13),COUNTIF(E13:AH13,"X"),"") -> 0 | AJ13: =IF(ISTEXT(C13),COUNTIF(E13:AH13,"T"),"") -> 0
A14: 3 | B14: =SF2_Default!C14 -> 19-00091 | C14: =SF2_Default!D14 -> CANDELARIA JAYREN D | AI14: =IF(ISTEXT(C14),COUNTIF(E14:AH14,"X"),"") -> 0 | AJ14: =IF(ISTEXT(C14),COUNTIF(E14:AH14,"T"),"") -> 0
A15: 4 | B15: =SF2_Default!C15 -> 18-00355 | C15: =SF2_Default!D15 -> CAY ROJER JYUAN P | AI15: =IF(ISTEXT(C15),COUNTIF(E15:AH15,"X"),"") -> 0 | AJ15: =IF(ISTEXT(C15),COUNTIF(E15:AH15,"T"),"") -> 0
A16: 5 | B16: =SF2_Default!C16 -> 25-000460 | C16: =SF2_Default!D16 -> CEZAR JOHN MANUEL DE LEON | AI16: =IF(ISTEXT(C16),COUNTIF(E16:AH16,"X"),"") -> 0 | AJ16: =IF(ISTEXT(C16),COUNTIF(E16:AH16,"T"),"") -> 0
A17: 6 | B17: =SF2_Default!C17 -> 20-00075 | C17: =SF2_Default!D17 -> CONJE LEOBERT JOROS D | AI17: =IF(ISTEXT(C17),COUNTIF(E17:AH17,"X"),"") -> 0 | AJ17: =IF(ISTEXT(C17),COUNTIF(E17:AH17,"T"),"") -> 0
A18: 7 | B18: =SF2_Default!C18 -> 25-001588 | C18: =SF2_Default!D18 -> DE LEON MARCUS BRENT TITCO | AI18: =IF(ISTEXT(C18),COUNTIF(E18:AH18,"X"),"") -> 0 | AJ18: =IF(ISTEXT(C18),COUNTIF(E18:AH18,"T"),"") -> 0
A19: 8 | B19: =SF2_Default!C19 -> 19-00239 | C19: =SF2_Default!D19 -> DEL ROSARIO ROBIN DALE A | AI19: =IF(ISTEXT(C19),COUNTIF(E19:AH19,"X"),"") -> 0 | AJ19: =IF(ISTEXT(C19),COUNTIF(E19:AH19,"T"),"") -> 0
A20: 9 | B20: =SF2_Default!C20 -> 18-00100 | C20: =SF2_Default!D20 -> DIEGO DAN LEONARD Q | AI20: =IF(ISTEXT(C20),COUNTIF(E20:AH20,"X"),"") -> 0 | AJ20: =IF(ISTEXT(C20),COUNTIF(E20:AH20,"T"),"") -> 0
A21: 10 | B21: =SF2_Default!C21 -> 19-00097 | C21: =SF2_Default!D21 -> GAMBOA OLIVER FRANCOIS Z | AI21: =IF(ISTEXT(C21),COUNTIF(E21:AH21,"X"),"") -> 0 | AJ21: =IF(ISTEXT(C21),COUNTIF(E21:AH21,"T"),"") -> 0
A22: 11 | B22: =SF2_Default!C22 -> 25-000134 | C22: =SF2_Default!D22 -> GO KELLIN CHASE SAN PEDRO | AI22: =IF(ISTEXT(C22),COUNTIF(E22:AH22,"X"),"") -> 0 | AJ22: =IF(ISTEXT(C22),COUNTIF(E22:AH22,"T"),"") -> 0
A23: 12 | B23: =SF2_Default!C23 -> 25-000839 | C23: =SF2_Default!D23 -> MALINIS ANDREI JAMES PARAGATOS | AI23: =IF(ISTEXT(C23),COUNTIF(E23:AH23,"X"),"") -> 0 | AJ23: =IF(ISTEXT(C23),COUNTIF(E23:AH23,"T"),"") -> 0
... A61: 50 | B61: =SF2_Default!C61 -> 0 | C61: =SF2_Default!D61 -> 0 | AI61: =IF(ISTEXT(C61),COUNTIF(E61:AH61,"X"),"") | AJ61: =IF(ISTEXT(C61),COUNTIF(E61:AH61,"T"),"")
C62: =COUNTIF(C12:C61,"*") -> 21 | E62: =IF(ISNUMBER(E$10),COUNTIF(E12:E61,"X"),"") | F62: =IF(ISNUMBER(F$10),COUNTIF(F12:F61,"X"),"") | G62: =IF(ISNUMBER(G$10),COUNTIF(G12:G61,"X"),"") | H62: =IF(ISNUMBER(H$10),COUNTIF(H12:H61,"X"),"") | I62: =IF(ISNUMBER(I$10),COUNTIF(I12:I61,"X"),"") | J62: =IF(ISNUMBER(J$10),COUNTIF(J12:J61,"X"),"") | K62: =IF(ISNUMBER(K$10),COUNTIF(K12:K61,"X"),"") -> 0 | L62: =IF(ISNUMBER(L$10),COUNTIF(L12:L61,"X"),"") -> 0 | ... AH62: =IF(ISNUMBER(AH$10),COUNTIF(AH12:AH61,"X"),"") | AI62: =SUM(AI12:AI61) -> 0 | AJ62: =SUM(AJ12:AJ61) -> 0
A63: MALE | TOTAL Per Day >>> | E63: =IF(ISNUMBER(E$10),$C$62-E62,"") | F63: =IF(ISNUMBER(F$10),$C$62-F62,"") | G63: =IF(ISNUMBER(G$10),$C$62-G62,"") | H63: =IF(ISNUMBER(H$10),$C$62-H62,"") | I63: =IF(ISNUMBER(I$10),$C$62-I62,"") | J63: =IF(ISNUMBER(J$10),$C$62-J62,"") | K63: =IF(ISNUMBER(K$10),$C$62-K62,"") -> 21 | L63: =IF(ISNUMBER(L$10),$C$62-L62,"") -> 21 | ... AH63: =IF(ISNUMBER(AH$10),$C$62-AH62,"") | AI63: =SUM(E63:AH63) -> 336 | AJ63: <<< Total MALE present for the month
A64: 1 | B64: =SF2_Default!C63 -> 25-000800 | C64: =SF2_Default!D63 -> ANGELES ALLERIA JHANE TUBIANO | AI64: =IF(ISTEXT(C64),COUNTIF(E64:AH64,"X"),"") -> 0 | AJ64: =IF(ISTEXT(C64),COUNTIF(E64:AH64,"T"),"") -> 0
A65: 2 | B65: =SF2_Default!C64 -> 25-001230 | C65: =SF2_Default!D64 -> BELISARIO ELIJAH MIRIONETTE | AI65: =IF(ISTEXT(C65),COUNTIF(E65:AH65,"X"),"") -> 0 | AJ65: =IF(ISTEXT(C65),COUNTIF(E65:AH65,"T"),"") -> 0
A66: 3 | B66: =SF2_Default!C65 -> 18-003636 | C66: =SF2_Default!D65 -> BENEDICTO CASSANDRA VIELLE V | AI66: =IF(ISTEXT(C66),COUNTIF(E66:AH66,"X"),"") -> 0 | AJ66: =IF(ISTEXT(C66),COUNTIF(E66:AH66,"T"),"") -> 0
A67: 4 | B67: =SF2_Default!C66 -> 24-001215 | C67: =SF2_Default!D66 -> BONIFACIO MARY JOICE BONIFACIO | AI67: =IF(ISTEXT(C67),COUNTIF(E67:AH67,"X"),"") -> 0 | AJ67: =IF(ISTEXT(C67),COUNTIF(E67:AH67,"T"),"") -> 0
A68: 5 | B68: =SF2_Default!C67 -> 25-001589 | C68: =SF2_Default!D67 -> CABUSA KYRIE BLAIRE TENERIFE | AI68: =IF(ISTEXT(C68),COUNTIF(E68:AH68,"X"),"") -> 0 | AJ68: =IF(ISTEXT(C68),COUNTIF(E68:AH68,"T"),"") -> 0
A69: 6 | B69: =SF2_Default!C68 -> 22-000390 | C69: =SF2_Default!D68 -> DELA CRUZ BRINA MARCE GATUS | AI69: =IF(ISTEXT(C69),COUNTIF(E69:AH69,"X"),"") -> 0 | AJ69: =IF(ISTEXT(C69),COUNTIF(E69:AH69,"T"),"") -> 0
A70: 7 | B70: =SF2_Default!C69 -> 19-00080 | C70: =SF2_Default!D69 -> DELOS REYES KREEZHA CYLEE D | AI70: =IF(ISTEXT(C70),COUNTIF(E70:AH70,"X"),"") -> 0 | AJ70: =IF(ISTEXT(C70),COUNTIF(E70:AH70,"T"),"") -> 0
A71: 8 | B71: =SF2_Default!C70 -> 19-00075 | C71: =SF2_Default!D70 -> ESCOTO RICH ANNE MARY REYES | AI71: =IF(ISTEXT(C71),COUNTIF(E71:AH71,"X"),"") -> 0 | AJ71: =IF(ISTEXT(C71),COUNTIF(E71:AH71,"T"),"") -> 0
A72: 9 | B72: =SF2_Default!C71 -> 20-00037 | C72: =SF2_Default!D71 -> FORTUNO AZZURIE SOLAYMAN | AI72: =IF(ISTEXT(C72),COUNTIF(E72:AH72,"X"),"") -> 0 | AJ72: =IF(ISTEXT(C72),COUNTIF(E72:AH72,"T"),"") -> 0
A73: 10 | B73: =SF2_Default!C72 -> 25-000884 | C73: =SF2_Default!D72 -> FORTUNO JAYRA VALERIO | AI73: =IF(ISTEXT(C73),COUNTIF(E73:AH73,"X"),"") -> 0 | AJ73: =IF(ISTEXT(C73),COUNTIF(E73:AH73,"T"),"") -> 0
A74: 11 | B74: =SF2_Default!C73 -> 25-001164 | C74: =SF2_Default!D73 -> FUENTES BREEANA KLEIN ALMONIÑA | AI74: =IF(ISTEXT(C74),COUNTIF(E74:AH74,"X"),"") -> 0 | AJ74: =IF(ISTEXT(C74),COUNTIF(E74:AH74,"T"),"") -> 0
A75: 12 | B75: =SF2_Default!C74 -> 25-000191 | C75: =SF2_Default!D74 -> GABUTEN KEISZHA ANDREA ANTIOJO | AI75: =IF(ISTEXT(C75),COUNTIF(E75:AH75,"X"),"") -> 0 | AJ75: =IF(ISTEXT(C75),COUNTIF(E75:AH75,"T"),"") -> 0
... A113: 50 | B113: =SF2_Default!C112 -> 0 | C113: =SF2_Default!D112 -> 0 | AI113: =IF(ISTEXT(C113),COUNTIF(E113:AH113,"X"),"") | AJ113: =IF(ISTEXT(C113),COUNTIF(E113:AH113,"T"),"")
C114: =COUNTIF(C64:C113,"*") -> 22 | E114: =IF(ISNUMBER(E$10),COUNTIF(E64:E113,"X"),"") | F114: =IF(ISNUMBER(F$10),COUNTIF(F64:F113,"X"),"") | G114: =IF(ISNUMBER(G$10),COUNTIF(G64:G113,"X"),"") | H114: =IF(ISNUMBER(H$10),COUNTIF(H64:H113,"X"),"") | I114: =IF(ISNUMBER(I$10),COUNTIF(I64:I113,"X"),"") | J114: =IF(ISNUMBER(J$10),COUNTIF(J64:J113,"X"),"") | K114: =IF(ISNUMBER(K$10),COUNTIF(K64:K113,"X"),"") -> 0 | L114: =IF(ISNUMBER(L$10),COUNTIF(L64:L113,"X"),"") -> 0 | ... AH114: =IF(ISNUMBER(AH$10),COUNTIF(AH64:AH113,"X"),"") | AI114: =SUM(AI64:AI113) -> 0 | AJ114: =SUM(AJ64:AJ113) -> 0
A115: FEMALE | TOTAL Per Day >>> | E115: =IF(ISNUMBER(E$10),$C$114-E114,"") | F115: =IF(ISNUMBER(F$10),$C$114-F114,"") | G115: =IF(ISNUMBER(G$10),$C$114-G114,"") | H115: =IF(ISNUMBER(H$10),$C$114-H114,"") | I115: =IF(ISNUMBER(I$10),$C$114-I114,"") | J115: =IF(ISNUMBER(J$10),$C$114-J114,"") | K115: =IF(ISNUMBER(K$10),$C$114-K114,"") -> 22 | L115: =IF(ISNUMBER(L$10),$C$114-L114,"") -> 22 | ... AH115: =IF(ISNUMBER(AH$10),$C$114-AH114,"") | AI115: =SUM(E115:AH115) -> 352 | AJ115: <<< Total FEMALE present for the month
A116: Combined TOTAL PER DAY | E116: =IF(ISNUMBER(E$10),E63+E115,"") | F116: =IF(ISNUMBER(F$10),F63+F115,"") | G116: =IF(ISNUMBER(G$10),G63+G115,"") | H116: =IF(ISNUMBER(H$10),H63+H115,"") | I116: =IF(ISNUMBER(I$10),I63+I115,"") | J116: =IF(ISNUMBER(J$10),J63+J115,"") | K116: =IF(ISNUMBER(K$10),K63+K115,"") -> 43 | L116: =IF(ISNUMBER(L$10),L63+L115,"") -> 43 | ... AH116: =IF(ISNUMBER(AH$10),AH63+AH115,"") | AI116: =AI63+AI115 -> 688 | AJ116: <<< COMBINED total present for the month
C117: FOOTER
...

Sheet SF2_DEC
A2: School Form 2 (SF2) Daily Attendance Report of Learners
A3: (This replaces Form 1, Form 2 & STS Form 4 - Absenteeism and Dropout Profile)
G4: 1FBFCVJeD1oNUgr8CQcYAE59bhnLo5qru-QwdKVTqY24
C5: School ID | D5: =SF2_Default!G4 -> 406295 | K5: School Year | L5: =SF2_Default!Q6 -> 2026-2027 | R5: Report for the Month of | Y5: DECEMBER
C7: Name of School | D7: =SF2_Default!G6 -> MANILA CATHEDRAL SCHOOL | U7: Grade Level | Y7: =SF2_Default!V6 -> Grade 8 | AA7: Section | AI7: =SF2_Default!Y6 -> St. Faustina Kowalska
C9: (Last Name, First Name Middle Name) | E9: DECEMBER 2026 | AI9: Total for the Month | AK9: REMARKS (If DROPPED OUT, state reason, please refer to legend number 2. If TRANSFERRED IN/OUT, write the name of School.)
B10: ID NUMBER | C10: LEARNER'S NAME | F10: 1 | G10: 2 | H10: 3 | I10: 4 | K10: 7 | M10: 9 | N10: 10 | O10: 11 | P10: 12 | Q10: 14 | R10: 15 | S10: 16 | AI10: ABSENT | AJ10: TARDY
E11: M | F11: T | G11: W | H11: TH | I11: F | J11: S | K11: M | L11: T | M11: W | N11: TH | O11: F | P11: S | Q11: M | R11: T | S11: W | T11: TH | U11: F | V11: S | W11: M | X11: T | Y11: W | Z11: TH | AA11: F | AB11: S | AC11: M | AD11: T | AE11: W | AF11: TH | AG11: F
A12: 1 | B12: =SF2_Default!C12 -> 23-003330 | C12: =SF2_Default!D12 -> BONIFACIO LORD RANI KARL PAINAGA | AI12: =IF(ISTEXT(C12),COUNTIF(E12:AH12,"X"),"") -> 0 | AJ12: =IF(ISTEXT(C12),COUNTIF(E12:AH12,"T"),"") -> 0
A13: 2 | B13: =SF2_Default!C13 -> 25-001275 | C13: =SF2_Default!D13 -> BUCACAO JOHNREEVE KHARI ALFONSO | AI13: =IF(ISTEXT(C13),COUNTIF(E13:AH13,"X"),"") -> 0 | AJ13: =IF(ISTEXT(C13),COUNTIF(E13:AH13,"T"),"") -> 0
A14: 3 | B14: =SF2_Default!C14 -> 19-00091 | C14: =SF2_Default!D14 -> CANDELARIA JAYREN D | AI14: =IF(ISTEXT(C14),COUNTIF(E14:AH14,"X"),"") -> 0 | AJ14: =IF(ISTEXT(C14),COUNTIF(E14:AH14,"T"),"") -> 0
A15: 4 | B15: =SF2_Default!C15 -> 18-00355 | C15: =SF2_Default!D15 -> CAY ROJER JYUAN P | AI15: =IF(ISTEXT(C15),COUNTIF(E15:AH15,"X"),"") -> 0 | AJ15: =IF(ISTEXT(C15),COUNTIF(E15:AH15,"T"),"") -> 0
A16: 5 | B16: =SF2_Default!C16 -> 25-000460 | C16: =SF2_Default!D16 -> CEZAR JOHN MANUEL DE LEON | AI16: =IF(ISTEXT(C16),COUNTIF(E16:AH16,"X"),"") -> 0 | AJ16: =IF(ISTEXT(C16),COUNTIF(E16:AH16,"T"),"") -> 0
A17: 6 | B17: =SF2_Default!C17 -> 20-00075 | C17: =SF2_Default!D17 -> CONJE LEOBERT JOROS D | AI17: =IF(ISTEXT(C17),COUNTIF(E17:AH17,"X"),"") -> 0 | AJ17: =IF(ISTEXT(C17),COUNTIF(E17:AH17,"T"),"") -> 0
